Workbook

Sheet Actors
A1: Id | B1: NameId | C1: _ | D1: _ | E1: ClassId | F1: UnitType | G1: ImagePath | H1: InitLv | I1: MaxLv | J1: InitHp | K1: InitMp | L1: InitAtk | M1: InitDef | N1: InitSpd | O1: GrowthHp | P1: GrowthMp | Q1: GrowthAtk | R1: GrowthDef | S1: GrowthSpd | T1: Element1 | U1: Element2 | V1: Element3 | W1: Element4 | X1: Element5 | Y1: X | Z1: Y | AA1: Scale | AB1: AwakenX | AC1: AwakenY | AD1: AwakenScale | AE1: Kind1 | AF1: Kind2 | AG1: Kind3
A2: 1 | B2: 1 | C2: =INDEX(TextData!B:B,MATCH(B2,TextData!A:A)) -> ミカ | D2: =INDEX(TextData!C:C,MATCH(B2,TextData!A:A)) -> 【煉獄棘姫】 | E2: 1 | F2: 1 | G2: 0001 | H2: 1 | I2: 99 | J2: 39 | K2: 0 | L2: 30 | M2: 15 | N2: 15 | O2: 55 | P2: 0 | Q2: 60 | R2: 30 | S2: 35 | T2: 1 | U2: 2 | V2: 6 | W2: 3 | X2: 6 | Y2: -10 | Z2: -54 | AA2: 0.75 | AB2: 0 | AC2: 0 | AD2: 1 | AE2: 0 | AF2: 0 | AG2: 0
A3: 2 | B3: 2 | C3: =INDEX(TextData!B:B,MATCH(B3,TextData!A:A)) -> エリザベート | D3: =INDEX(TextData!C:C,MATCH(B3,TextData!A:A)) -> 【ChargeCommander】 | E3: 2 | F3: 1 | G3: 0002 | H3: 1 | I3: 99 | J3: 29 | K3: 0 | L3: 21 | M3: 5 | N3: 28 | O3: 60 | P3: 0 | Q3: 40 | R3: 10 | S3: 70 | T3: 2 | U3: 1 | V3: 5 | W3: 7 | X3: 3 | Y3: -20 | Z3: -52 | AA3: 0.71 | AB3: 0 | AC3: 0 | AD3: 1 | AE3: 0 | AF3: 0 | AG3: 0
A4: 3 | B4: 3 | C4: =INDEX(TextData!B:B,MATCH(B4,TextData!A:A)) -> アリエス | D4: =INDEX(TextData!C:C,MATCH(B4,TextData!A:A)) -> 【怠惰な守護少女】 | E4: 3 | F4: 2 | G4: 0003 | H4: 1 | I4: 99 | J4: 35 | K4: 0 | L4: 17 | M4: 12 | N4: 9 | O4: 85 | P4: 0 | Q4: 25 | R4: 40 | S4: 25 | T4: 3 | U4: 6 | V4: 1 | W4: 2 | X4: 6 | Y4: -10 | Z4: -64 | AA4: 0.82 | AB4: 0 | AC4: 0 | AD4: 1 | AE4: 0 | AF4: 0 | AG4: 0
A5: 4 | B5: 4 | C5: =INDEX(TextData!B:B,MATCH(B5,TextData!A:A)) -> シイナ | D5: =INDEX(TextData!C:C,MATCH(B5,TextData!A:A)) -> 【イノセント・リメディ】 | E5: 4 | F5: 4 | G5: 0004 | H5: 1 | I5: 99 | J5: 32 | K5: 0 | L5: 15 | M5: 7 | N5: 21 | O5: 85 | P5: 0 | Q5: 35 | R5: 15 | S5: 30 | T5: 4 | U5: 3 | V5: 3 | W5: 1 | X5: 7 | Y5: -4 | Z5: -68 | AA5: 0.8 | AB5: 0 | AC5: 0 | AD5: 1 | AE5: 0 | AF5: 0 | AG5: 0
A6: 5 | B6: 5 | C6: =INDEX(TextData!B:B,MATCH(B6,TextData!A:A)) -> レダ | D6: =INDEX(TextData!C:C,MATCH(B6,TextData!A:A)) -> 【Self-sacrifice】 | E6: 5 | F6: 5 | G6: 0005 | H6: 1 | I6: 99 | J6: 29 | K6: 0 | L6: 12 | M6: 9 | N6: 12 | O6: 70 | P6: 0 | Q6: 30 | R6: 40 | S6: 45 | T6: 4 | U6: 6 | V6: 2 | W6: 5 | X6: 1 | Y6: -8 | Z6: -44 | AA6: 0.82 | AB6: 0 | AC6: 0 | AD6: 1 | AE6: 0 | AF6: 0 | AG6: 0
A7: 6 | B7: 6 | C7: =INDEX(TextData!B:B,MATCH(B7,TextData!A:A)) -> リシェリ | D7: =INDEX(TextData!C:C,MATCH(B7,TextData!A:A)) -> 【Faked-Magician】 | E7: 6 | F7: 3 | G7: 0006 | H7: 1 | I7: 99 | J7: 30 | K7: 0 | L7: 20 | M7: 19 | N7: 20 | O7: 40 | P7: 0 | Q7: 50 | R7: 50 | S7: 50 | T7: 1 | U7: 6 | V7: 2 | W7: 6 | X7: 3 | Y7: 48 | Z7: -68 | AA7: 0.76 | AB7: 0 | AC7: 0 | AD7: 1 | AE7: 0 | AF7: 0 | AG7: 0
A8: 7 | B8: 7 | C8: =INDEX(TextData!B:B,MATCH(B8,TextData!A:A)) -> ユニ | D8: =INDEX(TextData!C:C,MATCH(B8,TextData!A:A)) -> 【奇跡の乙女】 | E8: 7 | F8: 3 | G8: 0007 | H8: 1 | I8: 99 | J8: 40 | K8: 0 | L8: 22 | M8: 18 | N8: 16 | O8: 65 | P8: 0 | Q8: 45 | R8: 40 | S8: 30 | T8: 4 | U8: 1 | V8: 4 | W8: 3 | X8: 4 | Y8: -20 | Z8: -60 | AA8: 0.79 | AB8: 0 | AC8: 0 | AD8: 1 | AE8: 0 | AF8: 0 | AG8: 0
A9: 8 | B9: 8 | C9: =INDEX(TextData!B:B,MATCH(B9,TextData!A:A)) -> マリーベル | D9: =INDEX(TextData!C:C,MATCH(B9,TextData!A:A)) -> 【唯心の在処】 | E9: 8 | F9: 2 | G9: 0008 | H9: 1 | I9: 99 | J9: 37 | K9: 0 | L9: 15 | M9: 21 | N9: 16 | O9: 80 | P9: 0 | Q9: 40 | R9: 60 | S9: 35 | T9: 6 | U9: 2 | V9: 1 | W9: 5 | X9: 4 | Y9: -52 | Z9: -52 | AA9: 0.8 | AB9: 0 | AC9: 0 | AD9: 1 | AE9: 0 | AF9: 0 | AG9: 0
A10: 9 | B10: 9 | C10: =INDEX(TextData!B:B,MATCH(B10,TextData!A:A)) -> ナツキ | D10: =INDEX(TextData!C:C,MATCH(B10,TextData!A:A)) -> 【黄昏ニヒリスト】 | E10: 9 | F10: 1 | G10: 0009 | H10: 1 | I10: 99 | J10: 34 | K10: 0 | L10: 25 | M10: 12 | N10: 24 | O10: 25 | P10: 0 | Q10: 65 | R10: 30 | S10: 50 | T10: 1 | U10: 4 | V10: 4 | W10: 7 | X10: 2 | Y10: -16 | Z10: -52 | AA10: 0.75 | AB10: 0 | AC10: 0 | AD10: 1 | AE10: 0 | AF10: 0 | AG10: 0
A11: 10 | B11: 10 | C11: =INDEX(TextData!B:B,MATCH(B11,TextData!A:A)) -> メリアドール | D11: =INDEX(TextData!C:C,MATCH(B11,TextData!A:A)) -> 【怨嗟の鎖】 | E11: 10 | F11: 5 | G11: 0010 | H11: 1 | I11: 99 | J11: 30 | K11: 0 | L11: 17 | M11: 7 | N11: 31 | O11: 45 | P11: 0 | Q11: 30 | R11: 20 | S11: 75 | T11: 4 | U11: 1 | V11: 6 | W11: 5 | X11: 2 | Y11: 12 | Z11: -64 | AA11: 0.77 | AB11: 0 | AC11: 0 | AD11: 1 | AE11: 0 | AF11: 0 | AG11: 0
A12: 11 | B12: 11 | C12: =INDEX(TextData!B:B,MATCH(B12,TextData!A:A)) -> セリナ | D12: =INDEX(TextData!C:C,MATCH(B12,TextData!A:A)) -> 【氷雪の勿忘草】 | E12: 11 | F12: 1 | G12: 0011 | H12: 1 | I12: 99 | J12: 33 | K12: 0 | L12: 18 | M12: 17 | N12: 18 | O12: 65 | P12: 0 | Q12: 40 | R12: 25 | S12: 30 | T12: 6 | U12: 6 | V12: 1 | W12: 3 | X12: 2 | Y12: 0 | Z12: -54 | AA12: 0.87 | AB12: 0 | AC12: 0 | AD12: 1 | AE12: 0 | AF12: 0 | AG12: 0

Sheet Learning
A1: ActorId | B1: SkillId | C1: Level
A2: 1 | B2: 11,21,31,1010,1060,100110,100120 | C2: 0
A3: 1 | B3: 11060 | C3: 11
A4: 1 | B4: 401060 | C4: 26
A5: 1 | B5: 1020 | C5: 41
A6: 2 | B6: 11,21,31,2010,2070,100210,100220
A7: 2 | B7: 12080 | C7: 11
A8: 2 | B8: 12040 | C8: 26
A9: 2 | B9: 2060 | C9: 41
A10: 3 | B10: 11,21,31,3010,3020,100310,100320
A11: 3 | B11: 13080 | C11: 11
A12: 3 | B12: 403010 | C12: 26
A13: 3 | B13: 3040 | C13: 41
A14: 4 | B14: 11,21,31,4010,4030,100410,100420
A15: 4 | B15: 14080 | C15: 11
A16: 4 | B16: 404030 | C16: 26
A17: 4 | B17: 4060 | C17: 41
A18: 5 | B18: 11,21,31,5010,5070,100510,100520
A19: 5 | B19: 15090 | C19: 11
A20: 5 | B20: 405070 | C20: 26
A21: 5 | B21: 5040 | C21: 41
A22: 6 | B22: 11,21,31,1010,1030,100610,100620
A23: 6 | B23: 11040 | C23: 11
A24: 6 | B24: 401030 | C24: 26
A25: 6 | B25: 1070 | C25: 41
A26: 7 | B26: 11,21,31,2010,2040,100710,100720
A27: 7 | B27: 12090 | C27: 11
A28: 7 | B28: 412090 | C28: 26
A29: 7 | B29: 2050 | C29: 41
A30: 8 | B30: 11,21,31,3010,3070,100810,100820
A31: 8 | B31: 13060 | C31: 11
A32: 8 | B32: 403070 | C32: 26
A33: 8 | B33: 3060 | C33: 41
A34: 9 | B34: 11,21,31,1010,1050,100910,100920
A35: 9 | B35: 11070 | C35: 11
A36: 9 | B36: 401050 | C36: 26
A37: 9 | B37: 1080 | C37: 41
A38: 10 | B38: 11,21,31,2010,2030,101010,101020
A39: 10 | B39: 12010 | C39: 11
A40: 10 | B40: 402030 | C40: 26
...

Sheet SkillTrigger
A1: ActorId | B1: SkillId | C1: TriggerType1 | D1: TriggerType2
A2: 1 | B2: 1060 | C2: 0 | D2: 0
A3: 1 | B3: 100120 | C3: 0 | D3: 0
A4: 1 | B4: 1010 | C4: 0 | D4: 0
A5: 1 | B5: 100110 | C5: 0 | D5: 0
A6: 1 | B6: 0 | C6: 0 | D6: 0
A7: 1 | B7: 0 | C7: 0 | D7: 0
A8: 1 | B8: 0 | C8: 0 | D8: 0
A9: 1 | B9: 0 | C9: 0 | D9: 0
A10: 1 | B10: 0 | C10: 0 | D10: 0
A11: 1 | B11: 0 | C11: 0 | D11: 0
A12: 2 | B12: 2070 | C12: 0 | D12: 0
A13: 2 | B13: 100220 | C13: 0 | D13: 0
... A112: 11 | B112: 0 | C112: 0 | D112: 0

Sheet TextData
A1: Id | B1: Text | C1: SubName | D1: Feature
A2: 1 | B2: ミカ | C2: 【煉獄棘姫】 | D2: 高い攻撃性能を持つアタッカー。 全体的にステータスが高く、赤属性魔法を習得することでさらに攻撃性能を伸ばすことができる。
A3: 2 | B3: エリザベート | C3: 【ChargeCommander】 | D3: 回避率を上げて攻撃を避けるアタッカー。 打たれ弱いがSPDが高く、回避率をアップする雷属性魔法を習得しやすい。
A4: 3 | B4: アリエス | C4: 【怠惰な守護少女】 | D4: 相手の攻撃を跳ね返すディフェンダー。 受けた攻撃ダメージの一部を跳ね返す「カウンターオーラ」を使うことができる。
A5: 4 | B5: シイナ | C5: 【イノセント・リメディ】 | D5: 回復に特化したヒーラー。 全体的にステータスが低いが、味方のHpを回復する「ヒーリング」を使うことができる。
A6: 5 | B6: レダ | C6: 【Self-sacrifice】 | D6: 相手の攻撃性能を下げるジャマー。 「シェイディークラウド」で味方が受けるダメージを抑えたり、「毒」でスリップダメージを与える魔法を使うことができる。
A7: 6 | B7: リシェリ | C7: 【Faked-Magician】 | D7: 味方のCTを短縮することができるサポーター。 CT（魔法を再使用するまでのターン数）を短縮しパーティ全体の補助をすることができる。
A8: 7 | B8: ユニ | C8: 【奇跡の乙女】 | D8: 味方の行動待機時間を短くするサポーター。 「アウトオブオーダー」で両隣に配置した味方の行動待機時間を短縮したり、味方のATK・DEFをアップするバフ魔法を使うことができる。
A9: 8 | B9: マリーベル | C9: 【唯心の在処】 | D9: 味方の攻撃を代わりに受け持つディフェンダー。 「アクアミラージュ」で一定回数攻撃を無効にしたり、味方の攻撃を代わりに受けパーティの生存率を上げることができる。
A10: 9 | B10: ナツキ | C10: 【黄昏ニヒリスト】 | D10: 攻撃回数の多い攻撃性能を持つアタッカー。 Hpが低いがATKが高く、攻撃回数の多い「フレイムレイン」を使うことができる。
A11: 10 | B11: メリアドール | C11: 【怨嗟の鎖】 | D11: SPD性能に特化したジャマー。 「ショックインパルス」で相手を行動不可にすることができる。
A12: 11 | B12: セリナ | C12: 【氷雪の勿忘草】 | D12: 凍結攻撃を主体とするアタッカー。 「ディープフリーズ」で攻撃時に一定量のダメージを受ける「凍結」状態にし、凍結効果をさらにアップすることで自滅に追い込むことができる。
