Workbook

Sheet Skills
A1: Id | B1: NameId | C1: Name | D1: IconIndex | E1: _ | F1: AnimationId | G1: AnimationType | H1: _ | I1: CountTurn | J1: Rank | K1: Attribute | L1: _ | M1: SkillType | N1: _ | O1: TargetType | P1: _ | Q1: ScopeType | R1: _ | S1: Range | T1: RepeatTime | U1: AliveOnly | V1: TimingOnlyCount
A2: 0 | B2: 0 | C2: =INDEX(TextData!B:B,MATCH(B2,TextData!A:A)) -> - | D2: 0 | E2: =INDEX(Define!X:X,MATCH(D2,Define!W:W)) -> なし | F2: 0 | G2: 0 | H2: =INDEX(Define!B:B,MATCH(G2,Define!A:A)) -> なし | I2: 0 | J2: 0 | K2: 0 | L2: =INDEX(Define!E:E,MATCH(K2,Define!D:D)) -> なし | M2: 0 | N2: =INDEX(Define!H:H,MATCH(M2,Define!G:G)) -> なし | O2: 0 | P2: =INDEX(Define!K:K,MATCH(O2,Define!J:J)) -> なし | Q2: 0 | R2: =INDEX(Define!N:N,MATCH(Q2,Define!M:M)) -> なし | S2: 1 | T2: 1 | U2: 1 | V2: 0
A3: 1 | B3: 1 | C3: =INDEX(TextData!B:B,MATCH(B3,TextData!A:A)) -> はずす | D3: 0 | E3: =INDEX(Define!X:X,MATCH(D3,Define!W:W)) -> なし | F3: 0 | G3: 0 | H3: =INDEX(Define!B:B,MATCH(G3,Define!A:A)) -> なし | I3: 0 | J3: 0 | K3: 0 | L3: =INDEX(Define!E:E,MATCH(K3,Define!D:D)) -> なし | M3: 0 | N3: =INDEX(Define!H:H,MATCH(M3,Define!G:G)) -> なし | O3: 0 | P3: =INDEX(Define!K:K,MATCH(O3,Define!J:J)) -> なし | Q3: 0 | R3: =INDEX(Define!N:N,MATCH(Q3,Define!M:M)) -> なし | S3: 1 | T3: 1 | U3: 1 | V3: 0
A4: 2 | B4: 1 | C4: =INDEX(TextData!B:B,MATCH(B4,TextData!A:A)) -> はずす | D4: 1 | E4: =INDEX(Define!X:X,MATCH(D4,Define!W:W)) -> 元素 | F4: 0 | G4: 1 | H4: =INDEX(Define!B:B,MATCH(G4,Define!A:A)) -> 単体 | I4: 0 | J4: 0 | K4: 0 | L4: =INDEX(Define!E:E,MATCH(K4,Define!D:D)) -> なし | M4: 1 | N4: =INDEX(Define!H:H,MATCH(M4,Define!G:G)) -> 魔法 | O4: 1 | P4: =INDEX(Define!K:K,MATCH(O4,Define!J:J)) -> 相手 | Q4: 1 | R4: =INDEX(Define!N:N,MATCH(Q4,Define!M:M)) -> 単体 | S4: 2 | T4: 1 | U4: 1 | V4: 0
A5: 11 | B5: 11 | C5: =INDEX(TextData!B:B,MATCH(B5,TextData!A:A)) -> 覚醒 | D5: 5 | E5: =INDEX(Define!X:X,MATCH(D5,Define!W:W)) -> 超次元 | F5: 11 | G5: 1 | H5: =INDEX(Define!B:B,MATCH(G5,Define!A:A)) -> 単体 | I5: 0 | J5: 0 | K5: 0 | L5: =INDEX(Define!E:E,MATCH(K5,Define!D:D)) -> なし | M5: 1 | N5: =INDEX(Define!H:H,MATCH(M5,Define!G:G)) -> 魔法 | O5: 4 | P5: =INDEX(Define!K:K,MATCH(O5,Define!J:J)) -> 自身 | Q5: 4 | R5: =INDEX(Define!N:N,MATCH(Q5,Define!M:M)) -> 自身 | S5: 1 | T5: 1 | U5: 1 | V5: 0
A6: 21 | B6: 21 | C6: =INDEX(TextData!B:B,MATCH(B6,TextData!A:A)) -> 覚醒解除 | D6: 5 | E6: =INDEX(Define!X:X,MATCH(D6,Define!W:W)) -> 超次元 | F6: 0 | G6: 1 | H6: =INDEX(Define!B:B,MATCH(G6,Define!A:A)) -> 単体 | I6: 0 | J6: 0 | K6: 0 | L6: =INDEX(Define!E:E,MATCH(K6,Define!D:D)) -> なし | M6: 1 | N6: =INDEX(Define!H:H,MATCH(M6,Define!G:G)) -> 魔法 | O6: 4 | P6: =INDEX(Define!K:K,MATCH(O6,Define!J:J)) -> 自身 | Q6: 4 | R6: =INDEX(Define!N:N,MATCH(Q6,Define!M:M)) -> 自身 | S6: 1 | T6: 1 | U6: 1 | V6: 0
A7: 31 | B7: 31 | C7: =INDEX(TextData!B:B,MATCH(B7,TextData!A:A)) -> 拘束制御 | D7: 3 | E7: =INDEX(Define!X:X,MATCH(D7,Define!W:W)) -> 理術 | F7: 0 | G7: 1 | H7: =INDEX(Define!B:B,MATCH(G7,Define!A:A)) -> 単体 | I7: 0 | J7: 0 | K7: 2 | L7: =INDEX(Define!E:E,MATCH(K7,Define!D:D)) -> 雷 | M7: 0 | N7: =INDEX(Define!H:H,MATCH(M7,Define!G:G)) -> なし | O7: 1 | P7: =INDEX(Define!K:K,MATCH(O7,Define!J:J)) -> 相手 | Q7: 1 | R7: =INDEX(Define!N:N,MATCH(Q7,Define!M:M)) -> 単体 | S7: 2 | T7: 1 | U7: 1 | V7: 0
A8: 32 | B8: 32 | C8: 拘束ダメージ解除 | D8: 3 | E8: =INDEX(Define!X:X,MATCH(D8,Define!W:W)) -> 理術 | F8: 0 | G8: 1 | H8: =INDEX(Define!B:B,MATCH(G8,Define!A:A)) -> 単体 | I8: 0 | J8: 0 | K8: 2 | L8: =INDEX(Define!E:E,MATCH(K8,Define!D:D)) -> 雷 | M8: 0 | N8: =INDEX(Define!H:H,MATCH(M8,Define!G:G)) -> なし | O8: 4 | P8: =INDEX(Define!K:K,MATCH(O8,Define!J:J)) -> 自身 | Q8: 4 | R8: =INDEX(Define!N:N,MATCH(Q8,Define!M:M)) -> 自身 | S8: 1 | T8: 1 | U8: 1 | V8: 0
A9: 33 | B9: 33 | C9: =INDEX(TextData!B:B,MATCH(B9,TextData!A:A)) -> 居合 | D9: 3 | E9: =INDEX(Define!X:X,MATCH(D9,Define!W:W)) -> 理術 | F9: 0 | G9: 1 | H9: =INDEX(Define!B:B,MATCH(G9,Define!A:A)) -> 単体 | I9: 0 | J9: 0 | K9: 2 | L9: =INDEX(Define!E:E,MATCH(K9,Define!D:D)) -> 雷 | M9: 0 | N9: =INDEX(Define!H:H,MATCH(M9,Define!G:G)) -> なし | O9: 1 | P9: =INDEX(Define!K:K,MATCH(O9,Define!J:J)) -> 相手 | Q9: 1 | R9: =INDEX(Define!N:N,MATCH(Q9,Define!M:M)) -> 単体 | S9: 2 | T9: 1 | U9: 1 | V9: 0
A10: 1010 | B10: 1010 | C10: =INDEX(TextData!B:B,MATCH(B10,TextData!A:A)) -> ファイアボール | D10: 1 | E10: =INDEX(Define!X:X,MATCH(D10,Define!W:W)) -> 元素 | F10: 101 | G10: 1 | H10: =INDEX(Define!B:B,MATCH(G10,Define!A:A)) -> 単体 | I10: 0 | J10: 1 | K10: 1 | L10: =INDEX(Define!E:E,MATCH(K10,Define!D:D)) -> 炎 | M10: 1 | N10: =INDEX(Define!H:H,MATCH(M10,Define!G:G)) -> 魔法 | O10: 1 | P10: =INDEX(Define!K:K,MATCH(O10,Define!J:J)) -> 相手 | Q10: 1 | R10: =INDEX(Define!N:N,MATCH(Q10,Define!M:M)) -> 単体 | S10: 1 | T10: 1 | U10: 1 | V10: 0
A11: 1020 | B11: 1020 | C11: =INDEX(TextData!B:B,MATCH(B11,TextData!A:A)) -> バーンストーム | D11: 1 | E11: =INDEX(Define!X:X,MATCH(D11,Define!W:W)) -> 元素 | F11: 101 | G11: 2 | H11: =INDEX(Define!B:B,MATCH(G11,Define!A:A)) -> 列 | I11: 3 | J11: 2 | K11: 1 | L11: =INDEX(Define!E:E,MATCH(K11,Define!D:D)) -> 炎 | M11: 1 | N11: =INDEX(Define!H:H,MATCH(M11,Define!G:G)) -> 魔法 | O11: 1 | P11: =INDEX(Define!K:K,MATCH(O11,Define!J:J)) -> 相手 | Q11: 2 | R11: =INDEX(Define!N:N,MATCH(Q11,Define!M:M)) -> 列 | S11: 1 | T11: 1 | U11: 1 | V11: 0
A12: 1030 | B12: 1030 | C12: =INDEX(TextData!B:B,MATCH(B12,TextData!A:A)) -> ヒートスタンプ | D12: 2 | E12: =INDEX(Define!X:X,MATCH(D12,Define!W:W)) -> 光 | F12: 21 | G12: 1 | H12: =INDEX(Define!B:B,MATCH(G12,Define!A:A)) -> 単体 | I12: 2 | J12: 2 | K12: 1 | L12: =INDEX(Define!E:E,MATCH(K12,Define!D:D)) -> 炎 | M12: 1 | N12: =INDEX(Define!H:H,MATCH(M12,Define!G:G)) -> 魔法 | O12: 2 | P12: =INDEX(Define!K:K,MATCH(O12,Define!J:J)) -> 味方 | Q12: 1 | R12: =INDEX(Define!N:N,MATCH(Q12,Define!M:M)) -> 単体 | S12: 1 | T12: 1 | U12: 1 | V12: 0
A13: 1040 | B13: 1040 | C13: =INDEX(TextData!B:B,MATCH(B13,TextData!A:A)) -> ソードアダプト | D13: 4 | E13: =INDEX(Define!X:X,MATCH(D13,Define!W:W)) -> 精神 | F13: 51 | G13: 1 | H13: =INDEX(Define!B:B,MATCH(G13,Define!A:A)) -> 単体 | I13: 3 | J13: 2 | K13: 1 | L13: =INDEX(Define!E:E,MATCH(K13,Define!D:D)) -> 炎 | M13: 1 | N13: =INDEX(Define!H:H,MATCH(M13,Define!G:G)) -> 魔法 | O13: 4 | P13: =INDEX(Define!K:K,MATCH(O13,Define!J:J)) -> 自身 | Q13: 4 | R13: =INDEX(Define!N:N,MATCH(Q13,Define!M:M)) -> 自身 | S13: 1 | T13: 1 | U13: 1 | V13: 0
A14: 1050 | B14: 1050 | C14: =INDEX(TextData!B:B,MATCH(B14,TextData!A:A)) -> フレイムレイン | D14: 1 | E14: =INDEX(Define!X:X,MATCH(D14,Define!W:W)) -> 元素 | F14: 101 | G14: 1 | H14: =INDEX(Define!B:B,MATCH(G14,Define!A:A)) -> 単体 | I14: 2 | J14: 2 | K14: 1 | L14: =INDEX(Define!E:E,MATCH(K14,Define!D:D)) -> 炎 | M14: 1 | N14: =INDEX(Define!H:H,MATCH(M14,Define!G:G)) -> 魔法 | O14: 1 | P14: =INDEX(Define!K:K,MATCH(O14,Define!J:J)) -> 相手 | Q14: 1 | R14: =INDEX(Define!N:N,MATCH(Q14,Define!M:M)) -> 単体 | S14: 1 | T14: 5 | U14: 1 | V14: 0
A15: 1060 | B15: 1060 | C15: =INDEX(TextData!B:B,MATCH(B15,TextData!A:A)) -> イクスティンクション | D15: 1 | E15: =INDEX(Define!X:X,MATCH(D15,Define!W:W)) -> 元素 | F15: 101 | G15: 1 | H15: =INDEX(Define!B:B,MATCH(G15,Define!A:A)) -> 単体 | I15: 3 | J15: 2 | K15: 1 | L15: =INDEX(Define!E:E,MATCH(K15,Define!D:D)) -> 炎 | M15: 1 | N15: =INDEX(Define!H:H,MATCH(M15,Define!G:G)) -> 魔法 | O15: 1 | P15: =INDEX(Define!K:K,MATCH(O15,Define!J:J)) -> 相手 | Q15: 1 | R15: =INDEX(Define!N:N,MATCH(Q15,Define!M:M)) -> 単体 | S15: 1 | T15: 1 | U15: 1 | V15: 0
A16: 1070 | B16: 1070 | C16: =INDEX(TextData!B:B,MATCH(B16,TextData!A:A)) -> バーニングソウル | D16: 2 | E16: =INDEX(Define!X:X,MATCH(D16,Define!W:W)) -> 光 | F16: 101 | G16: 1 | H16: =INDEX(Define!B:B,MATCH(G16,Define!A:A)) -> 単体 | I16: 3 | J16: 2 | K16: 1 | L16: =INDEX(Define!E:E,MATCH(K16,Define!D:D)) -> 炎 | M16: 1 | N16: =INDEX(Define!H:H,MATCH(M16,Define!G:G)) -> 魔法 | O16: 2 | P16: =INDEX(Define!K:K,MATCH(O16,Define!J:J)) -> 味方 | Q16: 1 | R16: =INDEX(Define!N:N,MATCH(Q16,Define!M:M)) -> 単体 | S16: 1 | T16: 1 | U16: 1 | V16: 0
A17: 1080 | B17: 1080 | C17: =INDEX(TextData!B:B,MATCH(B17,TextData!A:A)) -> レイジングバウンサー | D17: 1 | E17: =INDEX(Define!X:X,MATCH(D17,Define!W:W)) -> 元素 | F17: 51 | G17: 1 | H17: =INDEX(Define!B:B,MATCH(G17,Define!A:A)) -> 単体 | I17: 2 | J17: 2 | K17: 1 | L17: =INDEX(Define!E:E,MATCH(K17,Define!D:D)) -> 炎 | M17: 1 | N17: =INDEX(Define!H:H,MATCH(M17,Define!G:G)) -> 魔法 | O17: 4 | P17: =INDEX(Define!K:K,MATCH(O17,Define!J:J)) -> 自身 | Q17: 4 | R17: =INDEX(Define!N:N,MATCH(Q17,Define!M:M)) -> 自身 | S17: 1 | T17: 1 | U17: 1 | V17: 0
A18: 2010 | B18: 2010 | C18: =INDEX(TextData!B:B,MATCH(B18,TextData!A:A)) -> ディスチャージ | D18: 1 | E18: =INDEX(Define!X:X,MATCH(D18,Define!W:W)) -> 元素 | F18: 201 | G18: 1 | H18: =INDEX(Define!B:B,MATCH(G18,Define!A:A)) -> 単体 | I18: 0 | J18: 1 | K18: 2 | L18: =INDEX(Define!E:E,MATCH(K18,Define!D:D)) -> 雷 | M18: 1 | N18: =INDEX(Define!H:H,MATCH(M18,Define!G:G)) -> 魔法 | O18: 1 | P18: =INDEX(Define!K:K,MATCH(O18,Define!J:J)) -> 相手 | Q18: 1 | R18: =INDEX(Define!N:N,MATCH(Q18,Define!M:M)) -> 単体 | S18: 1 | T18: 1 | U18: 1 | V18: 0
A19: 2020 | B19: 2020 | C19: =INDEX(TextData!B:B,MATCH(B19,TextData!A:A)) -> イベイドコード | D19: 4 | E19: =INDEX(Define!X:X,MATCH(D19,Define!W:W)) -> 精神 | F19: 51 | G19: 1 | H19: =INDEX(Define!B:B,MATCH(G19,Define!A:A)) -> 単体 | I19: 0 | J19: 2 | K19: 2 | L19: =INDEX(Define!E:E,MATCH(K19,Define!D:D)) -> 雷 | M19: 1 | N19: =INDEX(Define!H:H,MATCH(M19,Define!G:G)) -> 魔法 | O19: 4 | P19: =INDEX(Define!K:K,MATCH(O19,Define!J:J)) -> 自身 | Q19: 4 | R19: =INDEX(Define!N:N,MATCH(Q19,Define!M:M)) -> 自身 | S19: 1 | T19: 1 | U19: 1 | V19: 0
A20: 2030 | B20: 2030 | C20: =INDEX(TextData!B:B,MATCH(B20,TextData!A:A)) -> ショックインパルス | D20: 3 | E20: =INDEX(Define!X:X,MATCH(D20,Define!W:W)) -> 理術 | F20: 201 | G20: 1 | H20: =INDEX(Define!B:B,MATCH(G20,Define!A:A)) -> 単体 | I20: 3 | J20: 2 | K20: 2 | L20: =INDEX(Define!E:E,MATCH(K20,Define!D:D)) -> 雷 | M20: 1 | N20: =INDEX(Define!H:H,MATCH(M20,Define!G:G)) -> 魔法 | O20: 1 | P20: =INDEX(Define!K:K,MATCH(O20,Define!J:J)) -> 相手 | Q20: 1 | R20: =INDEX(Define!N:N,MATCH(Q20,Define!M:M)) -> 単体 | S20: 2 | T20: 1 | U20: 1 | V20: 0
... A205: 405080 | B205: 405080 | C205: =INDEX(TextData!B:B,MATCH(B205,TextData!A:A)) -> ポイズンブロウ+ | D205: 5 | E205: =INDEX(Define!X:X,MATCH(D205,Define!W:W)) -> 超次元 | F205: 501 | G205: 1 | H205: =INDEX(Define!B:B,MATCH(G205,Define!A:A)) -> 単体 | I205: 0 | J205: 120 | K205: 5 | L205: =INDEX(Define!E:E,MATCH(K205,Define!D:D)) -> 闇 | M205: 6 | N205: =INDEX(Define!H:H,MATCH(M205,Define!G:G)) -> 強化 | O205: 4 | P205: =INDEX(Define!K:K,MATCH(O205,Define!J:J)) -> 自身 | Q205: 4 | R205: =INDEX(Define!N:N,MATCH(Q205,Define!M:M)) -> 自身 | S205: 1 | T205: 1 | U205: 1 | V205: 0
A206: 411010 | B206: 411010 | C206: =INDEX(TextData!B:B,MATCH(B206,TextData!A:A)) -> ウルフソウル+ | D206: 6 | E206: =INDEX(Define!X:X,MATCH(D206,Define!W:W)) -> 自己強化 | G206: 1 | H206: =INDEX(Define!B:B,MATCH(G206,Define!A:A)) -> 単体 | I206: 0 | J206: 110 | K206: 1 | L206: =INDEX(Define!E:E,MATCH(K206,Define!D:D)) -> 炎 | M206: 6 | N206: =INDEX(Define!H:H,MATCH(M206,Define!G:G)) -> 強化 | O206: 4 | P206: =INDEX(Define!K:K,MATCH(O206,Define!J:J)) -> 自身 | Q206: 4 | R206: =INDEX(Define!N:N,MATCH(Q206,Define!M:M)) -> 自身 | S206: 1 | T206: 1 | U206: 1 | V206: 0
A207: 411020 | B207: 411020 | C207: =INDEX(TextData!B:B,MATCH(B207,TextData!A:A)) -> プリディカメント+ | D207: 6 | E207: =INDEX(Define!X:X,MATCH(D207,Define!W:W)) -> 自己強化 | G207: 1 | H207: =INDEX(Define!B:B,MATCH(G207,Define!A:A)) -> 単体 | I207: 0 | J207: 110 | K207: 1 | L207: =INDEX(Define!E:E,MATCH(K207,Define!D:D)) -> 炎 | M207: 6 | N207: =INDEX(Define!H:H,MATCH(M207,Define!G:G)) -> 強化 | O207: 4 | P207: =INDEX(Define!K:K,MATCH(O207,Define!J:J)) -> 自身 | Q207: 4 | R207: =INDEX(Define!N:N,MATCH(Q207,Define!M:M)) -> 自身 | S207: 1 | T207: 1 | U207: 1 | V207: 0
A208: 411030 | B208: 411030 | C208: =INDEX(TextData!B:B,MATCH(B208,TextData!A:A)) -> アサルトシフト+ | D208: 6 | E208: =INDEX(Define!X:X,MATCH(D208,Define!W:W)) -> 自己強化 | G208: 1 | H208: =INDEX(Define!B:B,MATCH(G208,Define!A:A)) -> 単体 | I208: 0 | J208: 110 | K208: 1 | L208: =INDEX(Define!E:E,MATCH(K208,Define!D:D)) -> 炎 | M208: 6 | N208: =INDEX(Define!H:H,MATCH(M208,Define!G:G)) -> 強化 | O208: 4 | P208: =INDEX(Define!K:K,MATCH(O208,Define!J:J)) -> 自身 | Q208: 4 | R208: =INDEX(Define!N:N,MATCH(Q208,Define!M:M)) -> 自身 | S208: 1 | T208: 1 | U208: 1 | V208: 0
A209: 411040 | B209: 411040 | C209: =INDEX(TextData!B:B,MATCH(B209,TextData!A:A)) -> アクティブギフト+ | D209: 6 | E209: =INDEX(Define!X:X,MATCH(D209,Define!W:W)) -> 自己強化 | G209: 1 | H209: =INDEX(Define!B:B,MATCH(G209,Define!A:A)) -> 単体 | I209: 0 | J209: 110 | K209: 1 | L209: =INDEX(Define!E:E,MATCH(K209,Define!D:D)) -> 炎 | M209: 6 | N209: =INDEX(Define!H:H,MATCH(M209,Define!G:G)) -> 強化 | O209: 4 | P209: =INDEX(Define!K:K,MATCH(O209,Define!J:J)) -> 自身 | Q209: 4 | R209: =INDEX(Define!N:N,MATCH(Q209,Define!M:M)) -> 自身 | S209: 1 | T209: 1 | U209: 1 | V209: 0
A210: 411050 | B210: 411050 | C210: =INDEX(TextData!B:B,MATCH(B210,TextData!A:A)) -> イグナイテッド+ | D210: 6 | E210: =INDEX(Define!X:X,MATCH(D210,Define!W:W)) -> 自己強化 | G210: 1 | H210: =INDEX(Define!B:B,MATCH(G210,Define!A:A)) -> 単体 | I210: 0 | J210: 110 | K210: 1 | L210: =INDEX(Define!E:E,MATCH(K210,Define!D:D)) -> 炎 | M210: 6 | N210: =INDEX(Define!H:H,MATCH(M210,Define!G:G)) -> 強化 | O210: 4 | P210: =INDEX(Define!K:K,MATCH(O210,Define!J:J)) -> 自身 | Q210: 4 | R210: =INDEX(Define!N:N,MATCH(Q210,Define!M:M)) -> 自身 | S210: 1 | T210: 1 | U210: 1 | V210: 0
A211: 411060 | B211: 411060 | C211: =INDEX(TextData!B:B,MATCH(B211,TextData!A:A)) -> ライジングファイア+ | D211: 6 | E211: =INDEX(Define!X:X,MATCH(D211,Define!W:W)) -> 自己強化 | G211: 1 | H211: =INDEX(Define!B:B,MATCH(G211,Define!A:A)) -> 単体 | I211: 0 | J211: 120 | K211: 1 | L211: =INDEX(Define!E:E,MATCH(K211,Define!D:D)) -> 炎 | M211: 6 | N211: =INDEX(Define!H:H,MATCH(M211,Define!G:G)) -> 強化 | O211: 4 | P211: =INDEX(Define!K:K,MATCH(O211,Define!J:J)) -> 自身 | Q211: 4 | R211: =INDEX(Define!N:N,MATCH(Q211,Define!M:M)) -> 自身 | S211: 1 | T211: 1 | U211: 1 | V211: 0
A212: 411070 | B212: 411070 | C212: =INDEX(TextData!B:B,MATCH(B212,TextData!A:A)) -> ルージュバック+ | D212: 6 | E212: =INDEX(Define!X:X,MATCH(D212,Define!W:W)) -> 自己強化 | G212: 1 | H212: =INDEX(Define!B:B,MATCH(G212,Define!A:A)) -> 単体 | I212: 0 | J212: 120 | K212: 1 | L212: =INDEX(Define!E:E,MATCH(K212,Define!D:D)) -> 炎 | M212: 6 | N212: =INDEX(Define!H:H,MATCH(M212,Define!G:G)) -> 強化 | O212: 4 | P212: =INDEX(Define!K:K,MATCH(O212,Define!J:J)) -> 自身 | Q212: 4 | R212: =INDEX(Define!N:N,MATCH(Q212,Define!M:M)) -> 自身 | S212: 1 | T212: 1 | U212: 1 | V212: 0
A213: 411080 | B213: 411080 | C213: =INDEX(TextData!B:B,MATCH(B213,TextData!A:A)) -> パワーエール+ | D213: 6 | E213: =INDEX(Define!X:X,MATCH(D213,Define!W:W)) -> 自己強化 | G213: 1 | H213: =INDEX(Define!B:B,MATCH(G213,Define!A:A)) -> 単体 | I213: 0 | J213: 120 | K213: 1 | L213: =INDEX(Define!E:E,MATCH(K213,Define!D:D)) -> 炎 | M213: 6 | N213: =INDEX(Define!H:H,MATCH(M213,Define!G:G)) -> 強化 | O213: 4 | P213: =INDEX(Define!K:K,MATCH(O213,Define!J:J)) -> 自身 | Q213: 4 | R213: =INDEX(Define!N:N,MATCH(Q213,Define!M:M)) -> 自身 | S213: 1 | T213: 1 | U213: 1 | V213: 0
A214: 411090 | B214: 411090 | C214: =INDEX(TextData!B:B,MATCH(B214,TextData!A:A)) -> スレイプニル+ | D214: 6 | E214: =INDEX(Define!X:X,MATCH(D214,Define!W:W)) -> 自己強化 | G214: 1 | H214: =INDEX(Define!B:B,MATCH(G214,Define!A:A)) -> 単体 | I214: 0 | J214: 120 | K214: 1 | L214: =INDEX(Define!E:E,MATCH(K214,Define!D:D)) -> 炎 | M214: 6 | N214: =INDEX(Define!H:H,MATCH(M214,Define!G:G)) -> 強化 | O214: 4 | P214: =INDEX(Define!K:K,MATCH(O214,Define!J:J)) -> 自身 | Q214: 4 | R214: =INDEX(Define!N:N,MATCH(Q214,Define!M:M)) -> 自身 | S214: 1 | T214: 1 | U214: 1 | V214: 0
A215: 412010 | B215: 412010 | C215: =INDEX(TextData!B:B,MATCH(B215,TextData!A:A)) -> エクステンション+ | D215: 6 | E215: =INDEX(Define!X:X,MATCH(D215,Define!W:W)) -> 自己強化 | G215: 1 | H215: =INDEX(Define!B:B,MATCH(G215,Define!A:A)) -> 単体 | I215: 0 | J215: 110 | K215: 2 | L215: =INDEX(Define!E:E,MATCH(K215,Define!D:D)) -> 雷 | M215: 6 | N215: =INDEX(Define!H:H,MATCH(M215,Define!G:G)) -> 強化 | O215: 4 | P215: =INDEX(Define!K:K,MATCH(O215,Define!J:J)) -> 自身 | Q215: 4 | R215: =INDEX(Define!N:N,MATCH(Q215,Define!M:M)) -> 自身 | S215: 1 | T215: 1 | U215: 1 | V215: 0
A216: 412020 | B216: 412020 | C216: =INDEX(TextData!B:B,MATCH(B216,TextData!A:A)) -> ヘブンリーラック+ | D216: 6 | E216: =INDEX(Define!X:X,MATCH(D216,Define!W:W)) -> 自己強化 | G216: 1 | H216: =INDEX(Define!B:B,MATCH(G216,Define!A:A)) -> 単体 | I216: 0 | J216: 110 | K216: 2 | L216: =INDEX(Define!E:E,MATCH(K216,Define!D:D)) -> 雷 | M216: 6 | N216: =INDEX(Define!H:H,MATCH(M216,Define!G:G)) -> 強化 | O216: 4 | P216: =INDEX(Define!K:K,MATCH(O216,Define!J:J)) -> 自身 | Q216: 4 | R216: =INDEX(Define!N:N,MATCH(Q216,Define!M:M)) -> 自身 | S216: 1 | T216: 1 | U216: 1 | V216: 0
A217: 412030 | B217: 412030 | C217: =INDEX(TextData!B:B,MATCH(B217,TextData!A:A)) -> スウィフトカレント+ | D217: 6 | E217: =INDEX(Define!X:X,MATCH(D217,Define!W:W)) -> 自己強化 | G217: 1 | H217: =INDEX(Define!B:B,MATCH(G217,Define!A:A)) -> 単体 | I217: 0 | J217: 110 | K217: 2 | L217: =INDEX(Define!E:E,MATCH(K217,Define!D:D)) -> 雷 | M217: 6 | N217: =INDEX(Define!H:H,MATCH(M217,Define!G:G)) -> 強化 | O217: 4 | P217: =INDEX(Define!K:K,MATCH(O217,Define!J:J)) -> 自身 | Q217: 4 | R217: =INDEX(Define!N:N,MATCH(Q217,Define!M:M)) -> 自身 | S217: 1 | T217: 1 | U217: 1 | V217: 0
... A250: 415090 | B250: 415090 | C250: =INDEX(TextData!B:B,MATCH(B250,TextData!A:A)) -> クイックカース+ | D250: 6 | E250: =INDEX(Define!X:X,MATCH(D250,Define!W:W)) -> 自己強化 | G250: 1 | H250: =INDEX(Define!B:B,MATCH(G250,Define!A:A)) -> 単体 | I250: 0 | J250: 120 | K250: 5 | L250: =INDEX(Define!E:E,MATCH(K250,Define!D:D)) -> 闇 | M250: 6 | N250: =INDEX(Define!H:H,MATCH(M250,Define!G:G)) -> 強化 | O250: 4 | P250: =INDEX(Define!K:K,MATCH(O250,Define!J:J)) -> 自身 | Q250: 4 | R250: =INDEX(Define!N:N,MATCH(Q250,Define!M:M)) -> 自身 | S250: 1 | T250: 1 | U250: 1 | V250: 0

Sheet Features
A1: SkillId | B1: _ | C1: FeatureType | D1: _ | E1: Param1 | F1: Param2 | G1: Param3 | H1: Rate
A2: 1 | B2: =INDEX(TextData!B:B,MATCH(A2,TextData!A:A)) -> はずす | C2: 1010 | D2: =INDEX(Define!Q:Q,MATCH(C2,Define!P:P)) -> Hpダメージ | E2: 100 | F2: 0 | G2: 0 | H2: 100
A3: 2 | B3: =INDEX(TextData!B:B,MATCH(A3,TextData!A:A)) -> はずす | C3: 1010 | D3: =INDEX(Define!Q:Q,MATCH(C3,Define!P:P)) -> Hpダメージ | E3: 50 | F3: 0 | G3: 0 | H3: 100
A4: 11 | B4: =INDEX(TextData!B:B,MATCH(A4,TextData!A:A)) -> 覚醒 | C4: 3010 | D4: =INDEX(Define!Q:Q,MATCH(C4,Define!P:P)) -> ステート付与 | E4: 1010 | F4: 0 | G4: 10 | H4: 100 | I4: =INDEX([1]TextData!B:B,MATCH(E4,[1]TextData!A:A)) -> 覚醒
A5: 21 | B5: =INDEX(TextData!B:B,MATCH(A5,TextData!A:A)) -> 覚醒解除 | C5: 3020 | D5: =INDEX(Define!Q:Q,MATCH(C5,Define!P:P)) -> ステート解除 | E5: 1010 | F5: 0 | G5: 0 | H5: 100 | I5: =INDEX([1]TextData!B:B,MATCH(E5,[1]TextData!A:A)) -> 覚醒
A6: 31 | B6: =INDEX(TextData!B:B,MATCH(A6,TextData!A:A)) -> 拘束制御 | C6: 1050 | D6: =INDEX(Define!Q:Q,MATCH(C6,Define!P:P)) -> 効果無視Hpダメージ | E6: 100 | F6: 0 | G6: 0 | H6: 100
A7: 31 | B7: =INDEX(TextData!B:B,MATCH(A7,TextData!A:A)) -> 拘束制御 | C7: 3020 | D7: =INDEX(Define!Q:Q,MATCH(C7,Define!P:P)) -> ステート解除 | E7: 2020 | F7: 0 | G7: 0 | H7: 100 | I7: =INDEX([1]TextData!B:B,MATCH(E7,[1]TextData!A:A)) -> 毒
A8: 32 | B8: =INDEX(TextData!B:B,MATCH(A8,TextData!A:A)) -> 拘束ダメージ解除 | C8: 3020 | D8: =INDEX(Define!Q:Q,MATCH(C8,Define!P:P)) -> ステート解除 | E8: 2021 | F8: 0 | G8: 0 | H8: 100 | I8: =INDEX([1]TextData!B:B,MATCH(E8,[1]TextData!A:A)) -> 毒
A9: 33 | B9: =INDEX(TextData!B:B,MATCH(A9,TextData!A:A)) -> 居合 | C9: 1010 | D9: =INDEX(Define!Q:Q,MATCH(C9,Define!P:P)) -> Hpダメージ | E9: 150 | F9: 0 | G9: 0 | H9: 100
A10: 33 | B10: =INDEX(TextData!B:B,MATCH(A10,TextData!A:A)) -> 居合 | C10: 5030 | D10: =INDEX(Define!Q:Q,MATCH(C10,Define!P:P)) -> 再行動する | E10: 0 | F10: 0 | G10: 0 | H10: 100
A11: 1010 | B11: =INDEX(TextData!B:B,MATCH(A11,TextData!A:A)) -> ファイアボール | C11: 1010 | D11: =INDEX(Define!Q:Q,MATCH(C11,Define!P:P)) -> Hpダメージ | E11: 150 | F11: 0 | G11: 0 | H11: 100
A12: 1020 | B12: =INDEX(TextData!B:B,MATCH(A12,TextData!A:A)) -> バーンストーム | C12: 1010 | D12: =INDEX(Define!Q:Q,MATCH(C12,Define!P:P)) -> Hpダメージ | E12: 150 | F12: 0 | G12: 0 | H12: 100
A13: 1030 | B13: =INDEX(TextData!B:B,MATCH(A13,TextData!A:A)) -> ヒートスタンプ | C13: 4020 | D13: =INDEX(Define!Q:Q,MATCH(C13,Define!P:P)) -> Ct回復 | E13: 1 | F13: 0 | G13: 0 | H13: 100
A14: 1040 | B14: =INDEX(TextData!B:B,MATCH(A14,TextData!A:A)) -> ソードアダプト | C14: 3010 | D14: =INDEX(Define!Q:Q,MATCH(C14,Define!P:P)) -> ステート付与 | E14: 2290 | F14: 999 | G14: 10 | H14: 100 | I14: =INDEX([1]TextData!B:B,MATCH(E14,[1]TextData!A:A)) -> ダメージ威力アップ
A15: 1050 | B15: =INDEX(TextData!B:B,MATCH(A15,TextData!A:A)) -> フレイムレイン | C15: 1010 | D15: =INDEX(Define!Q:Q,MATCH(C15,Define!P:P)) -> Hpダメージ | E15: 40 | F15: 0 | G15: 0 | H15: 100
A16: 1060 | B16: =INDEX(TextData!B:B,MATCH(A16,TextData!A:A)) -> イクスティンクション | C16: 1010 | D16: =INDEX(Define!Q:Q,MATCH(C16,Define!P:P)) -> Hpダメージ | E16: 300 | F16: 0 | G16: 0 | H16: 100
A17: 1070 | B17: =INDEX(TextData!B:B,MATCH(A17,TextData!A:A)) -> バーニングソウル | C17: 3060 | D17: =INDEX(Define!Q:Q,MATCH(C17,Define!P:P)) -> デバフステート解除 | E17: 0 | F17: 0 | G17: 0 | H17: 100
A18: 1080 | B18: =INDEX(TextData!B:B,MATCH(A18,TextData!A:A)) -> レイジングバウンサー | C18: 3040 | D18: =INDEX(Define!Q:Q,MATCH(C18,Define!P:P)) -> 次の行動まで有効なステート付与 | E18: 1070 | F18: 2 | G18: 30 | H18: 100 | I18: =INDEX([1]TextData!B:B,MATCH(E18,[1]TextData!A:A)) -> 会心率アップ
A19: 1080 | B19: =INDEX(TextData!B:B,MATCH(A19,TextData!A:A)) -> レイジングバウンサー | C19: 5030 | D19: =INDEX(Define!Q:Q,MATCH(C19,Define!P:P)) -> 再行動する | E19: 0 | F19: 0 | G19: 0 | H19: 100
A20: 2010 | B20: =INDEX(TextData!B:B,MATCH(A20,TextData!A:A)) -> ディスチャージ | C20: 1010 | D20: =INDEX(Define!Q:Q,MATCH(C20,Define!P:P)) -> Hpダメージ | E20: 150 | F20: 0 | G20: 0 | H20: 100
A21: 2020 | B21: =INDEX(TextData!B:B,MATCH(A21,TextData!A:A)) -> イベイドコード | C21: 3010 | D21: =INDEX(Define!Q:Q,MATCH(C21,Define!P:P)) -> ステート付与 | E21: 1090 | F21: 999 | G21: 15 | H21: 100 | I21: =INDEX([1]TextData!B:B,MATCH(E21,[1]TextData!A:A)) -> 回避アップ
A22: 2030 | B22: =INDEX(TextData!B:B,MATCH(A22,TextData!A:A)) -> ショックインパルス | C22: 1010 | D22: =INDEX(Define!Q:Q,MATCH(C22,Define!P:P)) -> Hpダメージ | E22: 150 | F22: 0 | G22: 0 | H22: 100
A23: 2030 | B23: =INDEX(TextData!B:B,MATCH(A23,TextData!A:A)) -> ショックインパルス | C23: 3010 | D23: =INDEX(Define!Q:Q,MATCH(C23,Define!P:P)) -> ステート付与 | E23: 2150 | F23: 100 | G23: 0 | H23: 100 | I23: =INDEX([1]TextData!B:B,MATCH(E23,[1]TextData!A:A)) -> スタン
A24: 2040 | B24: =INDEX(TextData!B:B,MATCH(A24,TextData!A:A)) -> トラストチェイン | C24: 5020 | D24: =INDEX(Define!Q:Q,MATCH(C24,Define!P:P)) -> Ap回復 | E24: 400 | F24: 0 | G24: 0 | H24: 100
A25: 2050 | B25: =INDEX(TextData!B:B,MATCH(A25,TextData!A:A)) -> スペルバニシング | C25: 1010 | D25: =INDEX(Define!Q:Q,MATCH(C25,Define!P:P)) -> Hpダメージ | E25: 150 | F25: 0 | G25: 0 | H25: 100
A26: 2050 | B26: =INDEX(TextData!B:B,MATCH(A26,TextData!A:A)) -> スペルバニシング | C26: 3010 | D26: =INDEX(Define!Q:Q,MATCH(C26,Define!P:P)) -> ステート付与 | E26: 2320 | F26: 0 | G26: 0 | H26: 100 | I26: =INDEX([1]TextData!B:B,MATCH(E26,[1]TextData!A:A)) -> バフ解除
A27: 2060 | B27: =INDEX(TextData!B:B,MATCH(A27,TextData!A:A)) -> アーテニーストライク | C27: 1010 | D27: =INDEX(Define!Q:Q,MATCH(C27,Define!P:P)) -> Hpダメージ | E27: 150 | F27: 0 | G27: 0 | H27: 100
A28: 2060 | B28: =INDEX(TextData!B:B,MATCH(A28,TextData!A:A)) -> アーテニーストライク | C28: 11010 | D28: =INDEX(Define!Q:Q,MATCH(C28,Define!P:P)) -> 命中判定しない | E28: 0 | F28: 0 | G28: 0 | H28: 100
A29: 2060 | B29: =INDEX(TextData!B:B,MATCH(A29,TextData!A:A)) -> アーテニーストライク | C29: 7020 | D29: =INDEX(Define!Q:Q,MATCH(C29,Define!P:P)) -> 行動後条件付きスキル | E29: 2061 | F29: 0 | G29: 0 | H29: 100
A30: 2060 | B30: =INDEX(TextData!B:B,MATCH(A30,TextData!A:A)) -> アーテニーストライク | C30: 5011 | D30: =INDEX(Define!Q:Q,MATCH(C30,Define!P:P)) -> 行動後ApがParam1割 | E30: 50 | F30: 0 | G30: 0 | H30: 100
A31: 2061 | B31: =INDEX(TextData!B:B,MATCH(A31,TextData!A:A)) -> アーテニーストライク | C31: 4020 | D31: =INDEX(Define!Q:Q,MATCH(C31,Define!P:P)) -> Ct回復 | E31: 2 | F31: 0 | G31: 0 | H31: 100
A32: 2070 | B32: =INDEX(TextData!B:B,MATCH(A32,TextData!A:A)) -> コンセントレイト | C32: 3040 | D32: =INDEX(Define!Q:Q,MATCH(C32,Define!P:P)) -> 次の行動まで有効なステート付与 | E32: 1080 | F32: 1 | G32: 25 | H32: 100 | I32: =INDEX([1]TextData!B:B,MATCH(E32,[1]TextData!A:A)) -> 命中アップ
A33: 2070 | B33: =INDEX(TextData!B:B,MATCH(A33,TextData!A:A)) -> コンセントレイト | C33: 3040 | D33: =INDEX(Define!Q:Q,MATCH(C33,Define!P:P)) -> 次の行動まで有効なステート付与 | E33: 1090 | F33: 1 | G33: 25 | H33: 100 | I33: =INDEX([1]TextData!B:B,MATCH(E33,[1]TextData!A:A)) -> 回避アップ
A34: 2070 | B34: =INDEX(TextData!B:B,MATCH(A34,TextData!A:A)) -> コンセントレイト | C34: 5030 | D34: =INDEX(Define!Q:Q,MATCH(C34,Define!P:P)) -> 再行動する | E34: 0 | F34: 0 | G34: 0 | H34: 100
A35: 2080 | B35: =INDEX(TextData!B:B,MATCH(A35,TextData!A:A)) -> ディレイマジック | C35: 1010 | D35: =INDEX(Define!Q:Q,MATCH(C35,Define!P:P)) -> Hpダメージ | E35: 150 | F35: 0 | G35: 0 | H35: 100
A36: 2080 | B36: =INDEX(TextData!B:B,MATCH(A36,TextData!A:A)) -> ディレイマジック | C36: 4010 | D36: =INDEX(Define!Q:Q,MATCH(C36,Define!P:P)) -> Ctダメージ | E36: 1 | F36: 0 | G36: 0 | H36: 100
A37: 3010 | B37: =INDEX(TextData!B:B,MATCH(A37,TextData!A:A)) -> アイスブレイド | C37: 1010 | D37: =INDEX(Define!Q:Q,MATCH(C37,Define!P:P)) -> Hpダメージ | E37: 150 | F37: 0 | G37: 0 | H37: 100
A38: 3020 | B38: =INDEX(TextData!B:B,MATCH(A38,TextData!A:A)) -> カウンターオーラ | C38: 3010 | D38: =INDEX(Define!Q:Q,MATCH(C38,Define!P:P)) -> ステート付与 | E38: 2030 | F38: 2 | G38: 25 | H38: 100 | I38: =INDEX([1]TextData!B:B,MATCH(E38,[1]TextData!A:A)) -> カウンタ
A39: 3030 | B39: =INDEX(TextData!B:B,MATCH(A39,TextData!A:A)) -> ラインプロテクト | C39: 3010 | D39: =INDEX(Define!Q:Q,MATCH(C39,Define!P:P)) -> ステート付与 | E39: 1050 | F39: 4 | G39: 15 | H39: 100 | I39: =INDEX([1]TextData!B:B,MATCH(E39,[1]TextData!A:A)) -> 防御アップ
A40: 3040 | B40: =INDEX(TextData!B:B,MATCH(A40,TextData!A:A)) -> エスコートソール | C40: 3010 | D40: =INDEX(Define!Q:Q,MATCH(C40,Define!P:P)) -> ステート付与 | E40: 2130 | F40: 1 | G40: 25 | H40: 100 | I40: =INDEX([1]TextData!B:B,MATCH(E40,[1]TextData!A:A)) -> 挑発
...

Sheet Triggers
A1: SkillId | B1: _ | C1: TriggerType | D1: _ | E1: TriggerTiming | F1: Param1 | G1: Param2 | H1: Param3
A2: 2101 | B2: =INDEX(Skills!C:C,MATCH(A2,Skills!A:A)) -> ディレイマジック | C2: 20140 | D2: =INDEX(Define!V:V,MATCH(C2,Define!U:U)) -> 自身の攻撃で敵を倒す | E2: 2 | F2: 0 | G2: 0 | H2: 0
A3: 3021 | B3: =INDEX(Skills!C:C,MATCH(A3,Skills!A:A)) -> カウンターオーラ | C3: 6010 | D3: =INDEX(Define!V:V,MATCH(C3,Define!U:U)) -> StateId状態になっている | E3: 2 | F3: 2030 | G3: 0 | H3: 0
A4: 10010 | B4: =INDEX(Skills!C:C,MATCH(A4,Skills!A:A)) -> アンデッド | C4: 0 | D4: =INDEX(Define!V:V,MATCH(C4,Define!U:U)) -> なし | E4: 4 | F4: 0 | G4: 0 | H4: 0
A5: 10020 | B5: =INDEX(Skills!C:C,MATCH(A5,Skills!A:A)) -> エアリアル | C5: 14410 | D5: =INDEX(Define!V:V,MATCH(C5,Define!U:U)) -> Lvが〇以上 | E5: 4 | F5: 20 | G5: 0 | H5: 0
A6: 10030 | B6: =INDEX(Skills!C:C,MATCH(A6,Skills!A:A)) -> 悪魔 | C6: 0 | D6: =INDEX(Define!V:V,MATCH(C6,Define!U:U)) -> なし | E6: 4 | F6: 0 | G6: 0 | H6: 0
A7: 10040 | B7: =INDEX(Skills!C:C,MATCH(A7,Skills!A:A)) -> クリーチャー | C7: 14410 | D7: =INDEX(Define!V:V,MATCH(C7,Define!U:U)) -> Lvが〇以上 | E7: 4 | F7: 20 | G7: 0 | H7: 0
A8: 10050 | B8: =INDEX(Skills!C:C,MATCH(A8,Skills!A:A)) -> 野生の記憶 | C8: 14410 | D8: =INDEX(Define!V:V,MATCH(C8,Define!U:U)) -> Lvが〇以上 | E8: 4 | F8: 20 | G8: 0 | H8: 0
A9: 10060 | B9: =INDEX(Skills!C:C,MATCH(A9,Skills!A:A)) -> 変異生物 | C9: 14410 | D9: =INDEX(Define!V:V,MATCH(C9,Define!U:U)) -> Lvが〇以上 | E9: 4 | F9: 20 | G9: 0 | H9: 0
A10: 11010 | B10: =INDEX(Skills!C:C,MATCH(A10,Skills!A:A)) -> ウルフソウル | C10: 0 | D10: =INDEX(Define!V:V,MATCH(C10,Define!U:U)) -> なし | E10: 4 | F10: 0 | G10: 0 | H10: 0
A11: 11020 | B11: =INDEX(Skills!C:C,MATCH(A11,Skills!A:A)) -> プリディカメント | C11: 1010 | D11: =INDEX(Define!V:V,MATCH(C11,Define!U:U)) -> 自身のHpが〇%以下 | E11: 2 | F11: 25 | G11: 0 | H11: 0
A12: 11030 | B12: =INDEX(Skills!C:C,MATCH(A12,Skills!A:A)) -> アサルトシフト | C12: 0 | D12: =INDEX(Define!V:V,MATCH(C12,Define!U:U)) -> なし | E12: 4 | F12: 0 | G12: 0 | H12: 0
A13: 11040 | B13: =INDEX(Skills!C:C,MATCH(A13,Skills!A:A)) -> アクティブギフト | C13: 15011 | D13: =INDEX(Define!V:V,MATCH(C13,Define!U:U)) -> 味方が攻撃タイプの行動をしようとしている | E13: 33 | F13: 0 | G13: 0 | H13: 0
... A119: 301100 | B119: =INDEX(Skills!C:C,MATCH(A119,Skills!A:A)) -> ファーストテイク | C119: 0 | D119: =INDEX(Define!V:V,MATCH(C119,Define!U:U)) -> なし | E119: 4 | F119: 0 | G119: 0 | H119: 0

Sheet ScopeTriggers
A1: SkillId | B1: _ | C1: TriggerType | D1: _ | E1: TriggerTiming | F1: Param1 | G1: Param2 | H1: Param3
A2: 13050 | B2: =INDEX(Skills!C:C,MATCH(A2,Skills!A:A)) -> パッシブジャミング | C2: 18020 | D2: =INDEX(Define!V:V,MATCH(C2,Define!U:U)) -> 自分の敵である | E2: 0 | F2: 0 | G2: 0 | H2: 0
A3: 14060 | B3: =INDEX(Skills!C:C,MATCH(A3,Skills!A:A)) -> パッシブサプライ | C3: 18010 | D3: =INDEX(Define!V:V,MATCH(C3,Define!U:U)) -> 自分の味方である | E3: 0 | F3: 0 | G3: 0 | H3: 0
A4: 100610 | B4: =INDEX(Skills!C:C,MATCH(A4,Skills!A:A)) -> サンフレイム | C4: 7020 | D4: =INDEX(Define!V:V,MATCH(C4,Define!U:U)) -> 神化発動後 | E4: 0 | F4: 0 | G4: 0 | H4: 0
A5: 300210 | B5: =INDEX(Skills!C:C,MATCH(A5,Skills!A:A)) -> エーテルリチャージ | C5: 9030 | D5: =INDEX(Define!V:V,MATCH(C5,Define!U:U)) -> ターン数がparam1 x ターン数 + param2 | E5: 2 | F5: 3 | G5: 0 | H5: 1
A6: 300210 | B6: =INDEX(Skills!C:C,MATCH(A6,Skills!A:A)) -> エーテルリチャージ | C6: 16010 | D6: =INDEX(Define!V:V,MATCH(C6,Define!U:U)) -> 攻撃したのが自身 | E6: 2 | F6: 0 | G6: 0 | H6: 0
A7: 301010 | B7: =INDEX(Skills!C:C,MATCH(A7,Skills!A:A)) -> ディケイドリセット | C7: 9030 | D7: =INDEX(Define!V:V,MATCH(C7,Define!U:U)) -> ターン数がparam1 x ターン数 + param2 | E7: 2 | F7: 0 | G7: 10 | H7: 1
A8: 301010 | B8: =INDEX(Skills!C:C,MATCH(A8,Skills!A:A)) -> ディケイドリセット | C8: 16010 | D8: =INDEX(Define!V:V,MATCH(C8,Define!U:U)) -> 攻撃したのが自身 | E8: 2 | F8: 0 | G8: 0 | H8: 0
A9: 301020 | B9: =INDEX(Skills!C:C,MATCH(A9,Skills!A:A)) -> ウォーリアーブラッド | C9: 20140 | D9: =INDEX(Define!V:V,MATCH(C9,Define!U:U)) -> 自身の攻撃で敵を倒す | E9: 2 | F9: 0 | G9: 0 | H9: 0
A10: 301030 | B10: =INDEX(Skills!C:C,MATCH(A10,Skills!A:A)) -> トライアングルガード | C10: 9030 | D10: =INDEX(Define!V:V,MATCH(C10,Define!U:U)) -> ターン数がparam1 x ターン数 + param2 | E10: 2 | F10: 3 | G10: 0 | H10: 1
A11: 301030 | B11: =INDEX(Skills!C:C,MATCH(A11,Skills!A:A)) -> トライアングルガード | C11: 16010 | D11: =INDEX(Define!V:V,MATCH(C11,Define!U:U)) -> 攻撃したのが自身 | E11: 2 | F11: 0 | G11: 0 | H11: 0
A12: 301040 | B12: =INDEX(Skills!C:C,MATCH(A12,Skills!A:A)) -> セーフティバリア | C12: 9030 | D12: =INDEX(Define!V:V,MATCH(C12,Define!U:U)) -> ターン数がparam1 x ターン数 + param2 | E12: 2 | F12: 0 | G12: 2 | H12: 1
A13: 301040 | B13: =INDEX(Skills!C:C,MATCH(A13,Skills!A:A)) -> セーフティバリア | C13: 16010 | D13: =INDEX(Define!V:V,MATCH(C13,Define!U:U)) -> 攻撃したのが自身 | E13: 2 | F13: 0 | G13: 0 | H13: 0
A14: 301060 | B14: =INDEX(Skills!C:C,MATCH(A14,Skills!A:A)) -> セカンドステージ | C14: 12040 | D14: =INDEX(Define!V:V,MATCH(C14,Define!U:U)) -> 攻撃を受けた対象のHpがParam1%以下 Param2==1で生存判定しない | E14: 2 | F14: 0 | G14: 1 | H14: 0

Sheet TextData
A1: Id | B1: Text | C1: Help
A2: 0 | B2: - | C2: ""
A3: 1 | B3: はずす | C3: ""
A4: 11 | B4: 覚醒 | C4: 覚醒状態になる /s
A5: 21 | B5: 覚醒解除 | C5: \sの覚醒を解除
A6: 31 | B6: 拘束制御 | C6: \sにダメージ
A7: 32 | B7: 拘束ダメージ解除 | C7: ""
A8: 33 | B8: 居合 | C8: \sにダメージ
A9: 1010 | B9: ファイアボール | C9: \sにATKx/f[f,0,1]%ダメージ
A10: 1020 | B10: バーンストーム | C10: \sにATKx/f[f,0,1]%ダメージ
A11: 1030 | B11: ヒートスタンプ | C11: \sのCT-/f[f,0,1]
A12: 1040 | B12: ソードアダプト | C12: \sの与ダメージ率を/f[f,0,3]%アップ(永続) 重ね掛け可能
A13: 1050 | B13: フレイムレイン | C13: \sにATKx/f[f,0,1]%の5連ダメージ
... A38: 4040 | B38: リザイアフォトン | C38: \sにATKx/f[f,0,1]%ダメージ 味方全員に攻撃成功回数x/f[f,1,3]のHp回復
A39: 4050 | B39: べネディクション | C39: 自身以外のHpを/f[f,0,1]回復 | D39: アクトヒール
A40: 4060 | B40: ホーリーグレイス | C40: \sを蘇生してHpを/f[f,0,1]回復
A41: 4070 | B41: キュアエール | C41: \sのHpを/f[f,0,1]回復 状態異常を回復
A42: 4080 | B42: ラインバリア | C42: 1回だけ\sが受けるダメージを/f[f,0,3]%カット
A43: 5010 | B43: ダークプリズン | C43: \sにATKx/f[f,0,1]%ダメージ
A44: 5020 | B44: ユーサネイジア | C44: \sにATKx/f[f,0,1]%ダメージ
A45: 5030 | B45: ドレインヒール | C45: \sにATKx/f[f,0,1]%ダメージ ダメージの/f[f,0,3]%分Hp回復
A46: 5040 | B46: アビサルデスペア | C46: \sにATKx/f[f,0,1]%ダメージ /f[f,1,2]ターンの不治付与 /s
A47: 5050 | B47: ディプラヴィティ | C47: \sにATKx/f[f,0,1]%ダメージ CT+/f[f,1,1] | D47: ランペイジ,パッシブブレイク
A48: 5060 | B48: ダークネス | C48: \sに/f[f,0,2]ターン命中率/f[f,0,3]%ダウンを付与
A49: 5070 | B49: シェイディークラウド | C49: \sのATKを/f[f,0,3]ダウン
A50: 5080 | B50: ポイズンブロウ | C50: \sにATKx/f[f,0,1]%ダメージ /f[f,1,2]ターン/f[f,1,3]ダメージの毒付与 /s
A51: 10010 | B51: アンデッド | C51: (条件)Lv20以上 アンデッド状態になる 行動後自身のHpを/f[f,0,3]%回復する
A52: 10020 | B52: エアリアル | C52: (条件)Lv10以上 攻撃範囲が延長する /s
A53: 10030 | B53: 悪魔 | C53: (条件)Lv10以上 最大AP+/f[f,0,3]
A54: 10040 | B54: クリーチャー | C54: (条件)Lv10以上 最大Hpが/f[f,0,3]アップ
A55: 10050 | B55: 野生の記憶 | C55: (条件)Lv10以上 ATKが/f[f,0,3]アップ
A56: 10060 | B56: 変異生物 | C56: (条件)Lv10以上 DEFが/f[f,0,3]アップ
A57: 11010 | B57: ウルフソウル | C57: \sのATKが/f[f,0,3]アップ
A58: 11020 | B58: プリディカメント | C58: (条件)Hpが25%以下 \sのATKが/f[f,0,3]アップ
A59: 11030 | B59: アサルトシフト | C59: (条件)バトル開始時 \sのDEFが/f[f,0,3]ダウンしATKが/f[f,0,3]アップ
A60: 11040 | B60: アクティブギフト | C60: (条件)他の味方が攻撃する直前に発動 \sのCT-/f[f,0,1] | D60: アクティブギフト
A61: 11050 | B61: イグナイテッド | C61: (条件)覚醒状態になった時 (制限)バトル中1回まで \sのCT-/f[f,0,1]
A62: 11060 | B62: ライジングファイア | C62: (条件)自身の行動で敵を倒した時 \sのCT-/f[f,0,1]
A63: 11070 | B63: ルージュバック | C63: (条件)攻撃を受けた時 \sのATKが/f[f,0,3]アップ 最大5回まで重ね掛け可能
A64: 11080 | B64: パワーエール | C64: (条件)他の味方が攻撃する直前に発動 一回だけ\sのATKを/f[f,0,3]アップ
...

Sheet Define
A1: AnimationType | D1: Attribute | G1: SkillType | J1: TargetType | M1: Scope | P1: Feature | S1: State | U1: Trigger | W1: MagicType | Y1: TriggerTiming
A2: 0 | B2: なし | D2: 0 | E2: なし | G2: 0 | H2: なし | J2: 0 | K2: なし | M2: 0 | N2: なし | P2: 0 | Q2: ない | U2: 0 | V2: なし | W2: 0 | X2: なし | Y2: 0 | Z2: なし | AB2: 301 | AC2: Numinous加算
A3: 1 | B3: 単体 | D3: 1 | E3: 炎 | G3: 1 | H3: 魔法 | J3: 1 | K3: 相手 | M3: 1 | N3: 単体 | P3: 1010 | Q3: Hpダメージ | U3: 1010 | V3: 自身のHpが〇%以下 | W3: 1 | X3: 元素 | Y3: 1 | Z3: 使ったとき | AB3: 302 | AC3: Numinouse消費率
A4: 2 | B4: 列 | D4: 2 | E4: 雷 | G4: 2 | H4: パッシブ | J4: 2 | K4: 味方 | M4: 2 | N4: 列 | P4: 1020 | Q4: Hp吸収ダメージ | U4: 1020 | V4: 自身のHpが〇%以上 | W4: 2 | X4: 光 | Y4: 2 | Z4: 使った後 | AB4: 303 | AC4: 敵Lv
A5: 3 | B5: 全体 | D5: 3 | E5: 氷 | G5: 3 | H5: 神化 | J5: 3 | K5: 全員 | M5: 3 | N5: 全体 | P5: 1030 | Q5: Hp固定ダメージ | U5: 1030 | V5: Hp%〇以下の味方 | W5: 3 | X5: 理術 | Y5: 3 | Z5: 割り込み | AB5: 304 | AC5: SP加算
D6: 4 | E6: 光 | G6: 4 | H6: 覚醒 | J6: 4 | K6: 自身 | M6: 4 | N6: 自身 | P6: 1040 | Q6: 特定ステートダメージ | U6: 1040 | V6: Hp%〇以上の味方 | W6: 4 | X6: 精神 | Y6: 4 | Z6: バトル開始時 | AB6: 305 | AC6: 隷従属度
D7: 5 | E7: 闇 | G7: 5 | H7: レリック | J7: 6 | K7: 反撃 | M7: 5 | N7: 最前列のみ | P7: 1050 | Q7: 効果無視Hpダメージ | U7: 1050 | V7: Hp%〇以下の敵 | W7: 5 | X7: 超次元 | Y7: 5 | Z7: 行動開始前 | AB7: 306 | AC7: アルカナ変更
G8: 6 | H8: 強化 | J8: 7 | K8: 追撃 | M8: 11 | N8: 単体・自身を除く | P8: 1060 | Q8: Hp割合固定ダメージ | U8: 1060 | V8: Hp%〇以上の敵 | W8: 6 | X8: 自己強化 | Y8: 11 | Z8: Hpが減る | AB8: 307 | AC8: ステータスコスト減算
G9: 11 | H9: アルカナ使用 | J9: 11 | K9: Triggerの条件を満たす | M9: 12 | N9: 列・自身を除く | P9: 1070 | Q9: Hpダメージ割合追加ダメージ | U9: 1130 | V9: 最もHpが少ない味方 | W9: 7 | X9: 工作 | Y9: 20 | Z9: バトル開始時と行動開始前 | AB9: 308 | AC9: 敵前衛消滅
G10: 12 | H10: 転生 | J10: 101 | K10: パーティ | M10: 13 | N10: 全体・自身を除く | P10: 1080 | Q10: Hp犠牲ダメージ | U10: 1140 | V10: 最もHpが多い味方 | W10: 10 | X10: 半神 | Y10: 24 | Z10: バトル開始時と使った後 | AB10: 309 | AC10: 撃破SPアップ
M11: 21 | N11: ランダム | P11: 1090 | Q11: 受けたダメージ総計ダメージ | U11: 1150 | V11: 最もHpが少ない敵 | W11: 11 | X11: 覚醒 | Y11: 31 | Z11: 自身の行動前 | AB11: 310 | AC11: 属性適性増加
M12: 31 | N12: 単体と両隣 | P12: 1100 | Q12: Hp貫通ダメージ | U12: 1160 | V12: 最もHpが多い敵 | W12: 99 | X12: その他 | Y12: 32 | Z12: 相手の行動前 | AB12: 311 | AC12: 命令不可
M13: 32 | N13: 自分を除いた両隣 | P13: 1110 | Q13: 残りHp比例ダメージ | U13: 2010 | V13: 味方にHpが〇%以下がいる | Y13: 33 | Z13: 味方の行動前 | AB13: 401 | AC13: コマンドLvアップ
P14: 2010 | Q14: Hp回復 | U14: 3010 | V14: 自身のMpが〇以下 | Y14: 41 | Z14: かばう専用。割り込みの最優先 | AB14: 402 | AC14: ステータスアップ
P15: 2020 | Q15: 自身のHpを1にする | U15: 3020 | V15: 自身のMpが〇以上 | Y15: 51 | Z15: ターン開始前 | AB15: 403 | AC15: 魔法入手
P16: 2030 | Q16: 対象のHpを1にする | U16: 3030 | V16: Mp〇未満の味方 | Y16: 52 | Z16: ターン開始後 | AB16: 404 | AC16: 最大HpとMpアップ
P17: 2040 | Q17: Hpを分け与える | U17: 3040 | V17: Mp〇以上の味方 | AB17: 501 | AC17: ターン数アップ
P18: 2110 | Q18: 与ダメージを味方全体に回復 | U18: 3050 | V18: Mp〇未満の敵 | AB18: 502 | AC18: Lvアップ
P19: 2120 | Q19: 与ダメージを味方全体にMp回復 | U19: 3060 | V19: Mp〇以上の敵 | AB19: 503 | AC19: 習得コスト0
P20: 2130 | Q20: 攻撃成功で味方全体に回復 | U20: 4010 | V20: 戦闘不能が〇以上存在する | AB20: 504 | AC20: ロスト回避
P21: 3010 | Q21: ステート付与 | U21: 4020 | V21: 生存者が〇以上存在する | AB21: 505 | AC21: 素子補充確定ボーナス
P22: 3020 | Q22: ステート解除 | U22: 5010 | V22: 自分が前列にいる | AB22: 506 | AC22: コマンドコスト0
P23: 3030 | Q23: Abnormalステート解除 | U23: 5020 | V23: 自分が後列にいる | AB23: 507 | AC23: 属性適正値アップ
P24: 3040 | Q24: 次の行動まで有効なステート付与 | U24: 5030 | V24: 前列の味方を狙う | AB24: 508 | AC24: コマンドLvアップ
P25: 3050 | Q25: バフステート解除 | U25: 5040 | V25: 後列の味方を狙う | AB25: 509 | AC25: 魔法入手
P26: 3060 | Q26: デバフステート解除 | U26: 5050 | V26: 前列の敵を狙う
P27: 3070 | Q27: ステートの効果を変更 | U27: 5060 | V27: 後列の敵を狙う
P28: 4010 | Q28: Ctダメージ | U28: 5070 | V28: 人数が多い列の味方
P29: 4020 | Q29: Ct回復 | U29: 5080 | V29: 人数が多い列の敵
P30: 4030 | Q30: Ct吸収ダメージ | U30: 5090 | V30: 人数が少ない列の味方
P31: 4040 | Q31: 指定魔法のCｔ回復 | U31: 5100 | V31: 人数が少ない列の敵
P32: 5010 | Q32: 行動後Ap設定 | U32: 5110 | V32: 〇人以上いる列の味方
P33: 5011 | Q33: 行動後ApがParam1割 | U33: 5120 | V33: 〇人以上いる列の敵
P34: 5012 | Q34: ActionResult扱いでAP指定 | U34: 5130 | V34: 〇番目の味方
P35: 5020 | Q35: Ap回復 | U35: 5140 | V35: 〇番目の敵
P36: 5030 | Q36: 再行動する | U36: 6010 | V36: StateId状態になっている
P37: 5040 | Q37: 先制攻撃 | U37: 6020 | V37: StateId状態になっていない
... P58: 13010 | Q58: 対象のバフを奪い取る | U58: 7020 | V58: 神化発動後
U59: 7030 | V59: 神化発動前の味方
U60: 7040 | V60: 神化発動後の味方
...
