Workbook

Sheet Stages
A1: Id | B1: NameId | C1: AchieveTextId | D1: Selectable | E1: StageLv | F1: Turns | G1: InitMembers | H1: RandomTroopCount | I1: BGMId | J1: BossBGMId | K1: BackGround | L1: StageRect | M1: Reborn | N1: Alcana | O1: SaveLimit | P1: ContinueLimit | Q1: RankingStage | R1: SlotSave | S1: SubordinateValue | T1: UseSlot
A2: 0 | B2: 1 | C2: 10001 | D2: 0 | E2: 0 | F2: -1 | G2: 1,2,3,4,5,6,7,8,9,10,11 | H2: 15 | I2: 3 | J2: 11 | K2: NA_background image_3D like_404 | L2: 80 | M2: 0 | N2: 0 | O2: 4 | P2: 2 | Q2: 0 | R2: 0 | S2: 0 | T2: 0
A3: 1 | B3: 1 | C3: 10001 | D3: 1 | E3: 0 | F3: -1 | G3: 1,2,3,4,5,6,7,8,9,10,11 | H3: 15 | I3: 3 | J3: 11 | K3: NA_background image_3D like_404 | L3: 80 | M3: 0 | N3: 0 | O3: 4 | P3: 2 | Q3: 0 | R3: 0 | S3: 0 | T3: 0
A4: 2 | B4: 2 | C4: 10001 | D4: 1 | E4: 10 | F4: -1 | G4: 1,2,3,4,5,6,7,8,9,10,11 | H4: 15 | I4: 3 | J4: 11 | K4: clipart _0147 | L4: 80 | M4: 0 | N4: 0 | O4: 4 | P4: 2 | Q4: 0 | R4: 0 | S4: 0 | T4: 0
A5: 3 | B5: 3 | C5: 10001 | D5: 1 | E5: 20 | F5: -1 | G5: 1,2,3,4,5,6,7,8,9,10,11 | H5: 15 | I5: 3 | J5: 11 | K5: NA_background image_3D like_140 | L5: 80 | M5: 0 | N5: 0 | O5: 4 | P5: 2 | Q5: 0 | R5: 0 | S5: 0 | T5: 0
A6: 4 | B6: 4 | C6: 10001 | D6: 1 | E6: 30 | F6: -1 | G6: 1,2,3,4,5,6,7,8,9,10,11 | H6: 15 | I6: 3 | J6: 11 | K6: NA_background image_3D like_094 | L6: 80 | M6: 0 | N6: 0 | O6: 4 | P6: 2 | Q6: 0 | R6: 0 | S6: 0 | T6: 0
A7: 5 | B7: 5 | C7: 10001 | D7: 1 | E7: 40 | F7: -1 | G7: 1,2,3,4,5,6,7,8,9,10,11 | H7: 15 | I7: 3 | J7: 11 | K7: NA_Background image_Modern_012 | L7: 80 | M7: 0 | N7: 0 | O7: 4 | P7: 2 | Q7: 0 | R7: 0 | S7: 0 | T7: 0
A8: 6 | B8: 6 | C8: 10001 | D8: 1 | E8: 50 | F8: -1 | G8: 1,2,3,4,5,6,7,8,9,10,11 | H8: 15 | I8: 5 | J8: 16 | K8: NA_background image_3D like_365 | L8: 80 | M8: 0 | N8: 0 | O8: 4 | P8: 2 | Q8: 0 | R8: 0 | S8: 0 | T8: 0
A9: 7 | B9: 7 | C9: 10001 | D9: 1 | E9: 60 | F9: -1 | G9: 1,2,3,4,5,6,7,8,9,10,11 | H9: 15 | I9: 3 | J9: 11 | K9: NA_background image_3D like_404 | L9: 80 | M9: 0 | N9: 0 | O9: 4 | P9: 2 | Q9: 0 | R9: 0 | S9: 0 | T9: 0
A10: 8 | B10: 8 | C10: 10001 | D10: 1 | E10: 70 | F10: -1 | G10: 1,2,3,4,5,6,7,8,9,10,11 | H10: 15 | I10: 3 | J10: 11 | K10: NA_background image_3D like_404 | L10: 80 | M10: 0 | N10: 0 | O10: 4 | P10: 2 | Q10: 0 | R10: 0 | S10: 0 | T10: 0
A11: 100 | B11: 1 | C11: 10001 | D11: 0 | E11: 1 | F11: -1 | G11: 1,2,3,4,5,6,7,8,9,10,11 | H11: 15 | I11: 3 | J11: 11 | K11: NA_background image_3D like_404 | L11: 80 | M11: 0 | N11: 0 | O11: 4 | P11: 2 | Q11: 0 | R11: 0 | S11: 0 | T11: 0

Sheet StageEvents
A1: Id | B1: Turns | C1: Timing | D1: _ | E1: Type | F1: _ | G1: Param | H1: ReadFlag
A2: 1 | B2: 1 | C2: 1 | D2: =INDEX(Define!B:B,MATCH(C2,Define!A:A)) -> Tactics開始 | E2: 1 | F2: =INDEX(Define!E:E,MATCH(E2,Define!D:D)) -> コマンドを制限する | G2: 6 | H2: 0
A3: 1 | B3: 1 | C3: 1 | D3: =INDEX(Define!B:B,MATCH(C3,Define!A:A)) -> Tactics開始 | E3: 1 | F3: =INDEX(Define!E:E,MATCH(E3,Define!D:D)) -> コマンドを制限する | G3: 6 | H3: 0
A4: 1 | B4: 1 | C4: 1 | D4: =INDEX(Define!B:B,MATCH(C4,Define!A:A)) -> Tactics開始 | E4: 1 | F4: =INDEX(Define!E:E,MATCH(E4,Define!D:D)) -> コマンドを制限する | G4: 6 | H4: 0

Sheet StageSymbols
A1: Id | B1: Seek | C1: SeekIndex | D1: SymbolType | F1: Rate | G1: Param1 | H1: Param2 | I1: PrizeSetId | J1: ClearCount
A2: 0 | B2: 0 | C2: 0 | D2: 8 | E2: =INDEX(Define!J:J,MATCH(D2,Define!I:I)) -> SelectActor | F2: 100 | G2: 0 | H2: 0 | I2: 252 | J2: 0 | K2: 開始時に入手
A3: 1 | B3: 0 | C3: 0 | D3: 1 | E3: =INDEX(Define!J:J,MATCH(D3,Define!I:I)) -> Battle | F3: 100 | G3: -1 | H3: 0 | I3: 0 | J3: 0 | K3: Seek=0でランダム生成用
A4: 1 | B4: 1 | C4: 0 | D4: 1 | E4: =INDEX(Define!J:J,MATCH(D4,Define!I:I)) -> Battle | F4: 100 | G4: 1011 | H4: 0 | I4: 1011 | J4: 0 | K4: ウルフソウル
A5: 1 | B5: 2 | C5: 0 | D5: 6 | E5: =INDEX(Define!J:J,MATCH(D5,Define!I:I)) -> Resource | F5: 100 | G5: 15 | H5: 0 | I5: 0 | J5: 0 | K5: リソース
A6: 1 | B6: 3 | C6: 0 | D6: 1 | E6: =INDEX(Define!J:J,MATCH(D6,Define!I:I)) -> Battle | F6: 100 | G6: 1031 | H6: 0 | I6: 1031 | J6: 0 | K6: 中ボス
A7: 1 | B7: 3 | C7: 1 | D7: 1 | E7: =INDEX(Define!J:J,MATCH(D7,Define!I:I)) -> Battle | F7: 100 | G7: 1032 | H7: 0 | I7: 1032 | J7: 2 | K7: 中ボス
A8: 1 | B8: 4 | C8: 0 | D8: 1 | E8: =INDEX(Define!J:J,MATCH(D8,Define!I:I)) -> Battle | F8: 100 | G8: 1041 | H8: 0 | I8: 1041 | J8: 0 | K8: エクステンド
A9: 1 | B9: 4 | C9: 1 | D9: 1 | E9: =INDEX(Define!J:J,MATCH(D9,Define!I:I)) -> Battle | F9: 100 | G9: 1042 | H9: 0 | I9: 1042 | J9: 0 | K9: アーマーコード
A10: 1 | B10: 5 | C10: 0 | D10: 1 | E10: =INDEX(Define!J:J,MATCH(D10,Define!I:I)) -> Battle | F10: 100 | G10: 1051 | H10: 0 | I10: 1051 | J10: 0 | K10: ホープフルアイリス
A11: 1 | B11: 5 | C11: 1 | D11: 1 | E11: =INDEX(Define!J:J,MATCH(D11,Define!I:I)) -> Battle | F11: 100 | G11: 1052 | H11: 0 | I11: 1052 | J11: 0 | K11: イーグルアイ
A12: 1 | B12: 6 | C12: 0 | D12: 2 | E12: =INDEX(Define!J:J,MATCH(D12,Define!I:I)) -> Boss | F12: 100 | G12: 1101 | H12: 0 | I12: 1101 | J12: 0 | K12: ボス戦
A13: 1 | B13: 7 | C13: 0 | D13: 8 | E13: =INDEX(Define!J:J,MATCH(D13,Define!I:I)) -> SelectActor | F13: 100 | G13: 2 | H13: -1 | I13: 0 | J13: 0 | K13: 仲間選択 3人までランダム
A14: 2 | B14: 0 | C14: 0 | D14: 1 | E14: =INDEX(Define!J:J,MATCH(D14,Define!I:I)) -> Battle | F14: 100 | G14: -1 | H14: 0 | I14: 0 | J14: 0 | K14: Seek=0でランダム生成用
A15: 2 | B15: 1 | C15: 0 | D15: -1 | E15: =INDEX(Define!J:J,MATCH(D15,Define!I:I)) -> Random | F15: 100 | G15: 0 | H15: 0 | I15: 0 | J15: 0
A16: 2 | B16: 1 | C16: 1 | D16: -1 | E16: =INDEX(Define!J:J,MATCH(D16,Define!I:I)) -> Random | F16: 100 | G16: 0 | H16: 0 | I16: 0 | J16: 0
A17: 2 | B17: 2 | C17: 0 | D17: 201 | E17: =INDEX(Define!J:J,MATCH(D17,Define!I:I)) -> Group | F17: 100 | G17: 0 | H17: 0 | I17: 0 | J17: 0 | K17: 火属性ランダムドロップ
A18: 2 | B18: 2 | C18: 1 | D18: 202 | E18: =INDEX(Define!J:J,MATCH(D18,Define!I:I)) -> Group | F18: 100 | G18: 0 | H18: 0 | I18: 0 | J18: 0 | K18: 雷属性ランダムドロップ
A19: 2 | B19: 2 | C19: 2 | D19: 203 | E19: =INDEX(Define!J:J,MATCH(D19,Define!I:I)) -> Group | F19: 100 | G19: 0 | H19: 0 | I19: 0 | J19: 0 | K19: 氷属性ランダムドロップ
A20: 2 | B20: 3 | C20: 0 | D20: 204 | E20: =INDEX(Define!J:J,MATCH(D20,Define!I:I)) -> Group | F20: 100 | G20: 0 | H20: 0 | I20: 0 | J20: 0 | K20: 光属性ランダムドロップ
A21: 2 | B21: 3 | C21: 1 | D21: 205 | E21: =INDEX(Define!J:J,MATCH(D21,Define!I:I)) -> Group | F21: 100 | G21: 0 | H21: 0 | I21: 0 | J21: 0 | K21: 闇属性ランダムドロップ
A22: 2 | B22: 4 | C22: 0 | D22: 1 | E22: =INDEX(Define!J:J,MATCH(D22,Define!I:I)) -> Battle | F22: 100 | G22: 2041 | H22: 0 | I22: 2041 | J22: 0 | K22: 中ボス
A23: 2 | B23: 4 | C23: 1 | D23: 1 | E23: =INDEX(Define!J:J,MATCH(D23,Define!I:I)) -> Battle | F23: 100 | G23: 2042 | H23: 0 | I23: 2042 | J23: 2 | K23: 中ボスハード
A24: 2 | B24: 5 | C24: 0 | D24: 6 | E24: =INDEX(Define!J:J,MATCH(D24,Define!I:I)) -> Resource | F24: 100 | G24: 15 | H24: 0 | I24: 0 | J24: 0
A25: 2 | B25: 5 | C25: 1 | D25: 4 | E25: =INDEX(Define!J:J,MATCH(D25,Define!I:I)) -> Alcana | F25: 100 | G25: -1 | H25: 10 | I25: 0 | J25: 0 | K25: 魔法ランダムランク10
A26: 2 | B26: 6 | C26: 0 | D26: 2 | E26: =INDEX(Define!J:J,MATCH(D26,Define!I:I)) -> Boss | F26: 100 | G26: 2101 | H26: 0 | I26: 2101 | J26: 0 | K26: ボス戦
A27: 2 | B27: 6 | C27: 1 | D27: 2 | E27: =INDEX(Define!J:J,MATCH(D27,Define!I:I)) -> Boss | F27: 100 | G27: 2102 | H27: 0 | I27: 2102 | J27: 2 | K27: ボス戦
A28: 2 | B28: 7 | C28: 0 | D28: 8 | E28: =INDEX(Define!J:J,MATCH(D28,Define!I:I)) -> SelectActor | F28: 100 | G28: 4 | H28: -1 | I28: 0 | J28: 0 | K28: 仲間選択 3人までランダム
A29: 2 | B29: 7 | C29: 1 | D29: 4 | E29: =INDEX(Define!J:J,MATCH(D29,Define!I:I)) -> Alcana | F29: 100 | G29: -1 | H29: 200 | I29: 0 | J29: 0 | K29: レリック
A30: 3 | B30: 0 | C30: 0 | D30: 1 | E30: =INDEX(Define!J:J,MATCH(D30,Define!I:I)) -> Battle | F30: 90 | G30: -1 | H30: 0 | I30: 0 | J30: 0 | K30: Seek=0でランダム生成用
A31: 3 | B31: 0 | C31: 0 | D31: 6 | E31: =INDEX(Define!J:J,MATCH(D31,Define!I:I)) -> Resource | F31: 5 | G31: 10 | H31: 0 | I31: 0 | J31: 0 | K31: Seek=0でランダム生成用
A32: 3 | B32: 0 | C32: 0 | D32: 6 | E32: =INDEX(Define!J:J,MATCH(D32,Define!I:I)) -> Resource | F32: 3 | G32: 20 | H32: 0 | I32: 0 | J32: 0 | K32: Seek=0でランダム生成用
A33: 3 | B33: 0 | C33: 0 | D33: 6 | E33: =INDEX(Define!J:J,MATCH(D33,Define!I:I)) -> Resource | F33: 2 | G33: 30 | H33: 0 | I33: 0 | J33: 0 | K33: Seek=0でランダム生成用
A34: 3 | B34: 1 | C34: 0 | D34: -1 | E34: =INDEX(Define!J:J,MATCH(D34,Define!I:I)) -> Random | F34: 100 | G34: 0 | H34: 0 | I34: 0 | J34: 0
A35: 3 | B35: 1 | C35: 1 | D35: -1 | E35: =INDEX(Define!J:J,MATCH(D35,Define!I:I)) -> Random | F35: 100 | G35: 0 | H35: 0 | I35: 0 | J35: 0
A36: 3 | B36: 2 | C36: 0 | D36: -1 | E36: =INDEX(Define!J:J,MATCH(D36,Define!I:I)) -> Random | F36: 100 | G36: 0 | H36: 0 | I36: 0 | J36: 0
A37: 3 | B37: 2 | C37: 1 | D37: -1 | E37: =INDEX(Define!J:J,MATCH(D37,Define!I:I)) -> Random | F37: 100 | G37: 0 | H37: 0 | I37: 0 | J37: 0
A38: 3 | B38: 2 | C38: 2 | D38: 9 | E38: =INDEX(Define!J:J,MATCH(D38,Define!I:I)) -> Shop | F38: 100 | G38: -1 | H38: 0 | I38: 0 | J38: 0 | K38: ショップ
A39: 3 | B39: 3 | C39: 0 | D39: -1 | E39: =INDEX(Define!J:J,MATCH(D39,Define!I:I)) -> Random | F39: 100 | G39: 0 | H39: 0 | I39: 0 | J39: 0
A40: 3 | B40: 3 | C40: 1 | D40: -1 | E40: =INDEX(Define!J:J,MATCH(D40,Define!I:I)) -> Random | F40: 100 | G40: 0 | H40: 0 | I40: 0 | J40: 0
...

Sheet SymbolGroup
A1: GroupId | B1: SymbolType | C1: _ | D1: Rate | E1: Param1 | F1: Param2 | G1: PrizeSetId
A2: 201 | B2: 1 | C2: =INDEX(Define!J:J,MATCH(B2,Define!I:I)) -> Battle | D2: 50 | E2: 2201 | F2: 0 | G2: 11020
A3: 201 | B3: 1 | C3: =INDEX(Define!J:J,MATCH(B3,Define!I:I)) -> Battle | D3: 50 | E3: 2201 | F3: 0 | G3: 11030
A4: 201 | B4: 1 | C4: =INDEX(Define!J:J,MATCH(B4,Define!I:I)) -> Battle | D4: 50 | E4: 2201 | F4: 0 | G4: 11040
A5: 202 | B5: 1 | C5: =INDEX(Define!J:J,MATCH(B5,Define!I:I)) -> Battle | D5: 50 | E5: 2202 | F5: 0 | G5: 12020
A6: 202 | B6: 1 | C6: =INDEX(Define!J:J,MATCH(B6,Define!I:I)) -> Battle | D6: 50 | E6: 2202 | F6: 0 | G6: 12030
A7: 202 | B7: 1 | C7: =INDEX(Define!J:J,MATCH(B7,Define!I:I)) -> Battle | D7: 50 | E7: 2202 | F7: 0 | G7: 12040
A8: 203 | B8: 1 | C8: =INDEX(Define!J:J,MATCH(B8,Define!I:I)) -> Battle | D8: 50 | E8: 2203 | F8: 0 | G8: 13020
A9: 203 | B9: 1 | C9: =INDEX(Define!J:J,MATCH(B9,Define!I:I)) -> Battle | D9: 50 | E9: 2203 | F9: 0 | G9: 13030
A10: 203 | B10: 1 | C10: =INDEX(Define!J:J,MATCH(B10,Define!I:I)) -> Battle | D10: 50 | E10: 2203 | F10: 0 | G10: 13040
A11: 204 | B11: 1 | C11: =INDEX(Define!J:J,MATCH(B11,Define!I:I)) -> Battle | D11: 50 | E11: 2204 | F11: 0 | G11: 14010
A12: 204 | B12: 1 | C12: =INDEX(Define!J:J,MATCH(B12,Define!I:I)) -> Battle | D12: 50 | E12: 2204 | F12: 0 | G12: 14020
A13: 204 | B13: 1 | C13: =INDEX(Define!J:J,MATCH(B13,Define!I:I)) -> Battle | D13: 50 | E13: 2204 | F13: 0 | G13: 14030
... A16: 205 | B16: 1 | C16: =INDEX(Define!J:J,MATCH(B16,Define!I:I)) -> Battle | D16: 50 | E16: 2205 | F16: 0 | G16: 15050

Sheet Tutorials
A1: Id | B1: Turns | C1: Timing | D1: SceneType | E1: X | F1: Y | G1: Width | H1: Height

Sheet TextData
A1: Id | B1: Text | C1: Help
A2: 0 | B2: A.D.xxxx 永遠の終結と秩序の確立 | C2: 人類最後の日。天から彗星が落とされる。 熱波は三日間続き、不義者の罪は浄化された。 すべて理想世界に生まれ変わる為に。
A3: 1 | B3: AD.4036 VR催眠コレクティブ | D3: VR史における人類最大の事件。 <詳細> 何者かが世界VR管理政策期に搭載したVR脳チップを悪用し催眠術によって集団自決を引き起こした事件。 国際指名手配されたが犯人の特定にはいたらなかった。 <死者数> 約2500 <備考> 死者は若年層に集中している。 本当の原因は落雷によるものだが 詳細は一切公表されていない。
A4: 2 | B4: AD.3256 ホワイトヴェールの静寂 | C4: 「失われた過去に幸あれ」 人類の歴史は自然災害との戦いである。 我々は幾多の災害を乗り越え今日を迎えている。 しかしそれは歴史的な事実に他ならない。 これら全て悪神アンリ・マユが送り出す悪魔によって起きているのだ。 Normは悪魔を駆逐する。 いくか迎える最期の審判を迎えるために。 | D4: 異常現象により豪雪が大和中越山間部を覆った大災害。 <詳細> 大雪により多くの建物が雪の重みに耐え切れず倒壊。 交通は寸断され救助活動が遅れ 孤立した地域では命を落とす者が相次いだ。 <死者数> 約5万超 <備考> 命名は救助活動が駆けつけた時の様子に由来する。
A5: 3 | B5: AD.2869北極星の大異変 | C5: 「失われた過去に幸あれ」 Normは過去を改編する。 霊体の魔法使い達は時間を超越し悪魔を駆逐する。 一人でも多くの犠牲がなくなることを願って。 | D5: 北極星の位置や動きが突然変異し 地球の気候や天候に大きな影響を及ぼした一連の出来事。 <詳細> 海面上昇や地殻変動が活発化し地震や火山噴火が頻発した。 <死者数> 約3万 <備考> 大和全土を含む全世界広域にて発生。
A6: 4 | B6: AD.2404 アソ・カタストロフ | C6: 「失われた過去に幸あれ」 Normは現実を修正する。 悪魔を駆逐することは歴史修正の旅路である。 自然災害の存在がなくなることで生命を 未来に続く進化と調和を果たすために。 | D6: 日本の九州地方で発生した破局噴火。 <詳細> 火砕流が発生し、火山灰によりライフラインが完全に停止した。 <死者数> 約7万 <備考> 死者は火山灰降雨を原因とするものを含む
A7: 5 | B7: AD.2087 南海トラフ巨大地震 | C7: 「失われた過去に幸あれ」 Normは未来を結合する。 死者の魂は最期の審判へ続く光の橋を渡って再生する。 悪のない悠久に続く理想世界へ導くために。 | D7: 日本の南東部のプレートを震源とする巨大地震。 <詳細> 初動による大津波の被害は少なかったが、その後の孤立集落、医療崩壊、食料不足などの原因により多くの災害関連死者が発生した。 <死者数> 約25万 <備考> 死者は災害関連死の他に病死・餓死も含む
A8: 6 | B8: AD.2011 魂が潰えた日 | C8: 「失われた過去に幸あれ」 Normは災害を消去する。 悪魔によって潰えた魂は救済機会を与うるに値する。 最期の審判を迎えた終末で すべての悪が滅した新世界で 永遠の生命を手に入れるか、それは貴方次第。 | D8: 大和の東海域で発生した巨大地震。 <詳細> 地震により大きな揺れや大津波・火災などにより多くの被害をもたらした。 <死者数> 約2万 <備考> 死者は震災関連死も含む
A9: 7 | B9: A.D.1995 阪神・淡路大震災 | C9: 日本の東海地方で発生した巨大地震。 <詳細> 大都市の直下で発生した「都市直下型地震」によりライフラインに深刻な被害を与えた。 <死者数> 約7300 <備考> 淡路島を震源とする
A10: 8 | B10: A.D.1923 関東大震災 | C10: 日本の関東地方で発生した巨大地震。 <詳細> 地震により家屋の倒壊が強風により火災が広範囲に発生した。 <死者数> 約10万超 <備考> 死者は行方不明者も含む
A11: 10001 | B11: ?????? | C11: ""
A12: 10002 | B12: 回路を解析し使途を殲滅する | C12: ""
A13: 10003 | B13: 救済執行に成功しつづける | C13: ""

Sheet Define
A1: Timing | D1: Type | I1: SymbolType
A2: 0 | B2: なし | D2: 0 | E2: なし | I2: -1 | J2: Random
A3: 1 | B3: Tactics開始 | D3: 1 | E3: コマンドを制限する | I3: 0
A4: 2 | B4: Strategy開始 | D4: 2 | E4: バトルをチュートリアルで固定する | I4: 1 | J4: Battle
A5: 3 | B5: Battle開始 | D5: 3 | E5: 全員コマンドを選ばないと進まない | I5: 2 | J5: Boss
A6: 4 | B6: Battleコマンド後 | D6: 4 | E6: 隷従属度フラグを管理 | I6: 3 | J6: Recover
A7: 5 | B7: 神化した後 | D7: 5 | E7: アルカナフラグを管理 | I7: 4 | J7: Alcana
A8: 11 | B8: Tactics開始(UI表示前) | D8: 6 | E8: 仲間を選んで加入する | I8: 5 | J8: Actor
D9: 7 | E9: セーブを行う | I9: 6 | J9: Resource
D10: 8 | E10: ボスの選択番号を設定する | I10: 7 | J10: Rebirth
D11: 9 | E11: SPを消費しないと進まない | I11: 8 | J11: SelectActor
D12: 11 | E12: ADV再生 | I12: 9 | J12: Shop
D13: 12 | E13: IDにActorIDを加算してADV再生 | I13: 99 | J13: Group
D14: 13 | E14: ルート分岐イベント
D15: 14 | E15: ルート分岐パラメータ設定
D16: 15 | E16: ルート分岐ステージ移動
D17: 21 | E17: ステージクリア
D18: 31 | E18: ルート分岐でステージに移動
D19: 32 | E19: ルート分岐敵グループを生成
D20: 33 | E20: 表示残りターンをマスターから取得
D21: 41 | E21: 継承スキル演出開始
D22: 51 | E22: ステージ移動
D23: 61 | E23: 中ボスを設置する(コマンド制限判定あり)
D24: 62 | E24: 上位者ボスを設置する(コマンド制限判定あり)
D25: 201 | E25: サバイバルモードにする
